<?xml version="1.0"?>
<!--
  Dimensions

  Prop  : 5 inch
  Motor : model:  tbd
          mass:   tbd
          size:   tbd
          thrust: tbd
  ESC   : tbd
  Servo : model:  tbd
          mass:   tbd
          torque: tbd
          size:   tbd

  Wing:   span:   0.150m
          chord:  0.110m


  Wing joint position controllers

  gz topic -t /model/morphing_quad/joint/wing_front_left_joint/cmd_pos -m gz.msgs.Double -p "data: -1.57"


-->
<sdf version="1.9"> 
  <model name="morphing_quad">
    <pose>0 0 0 0 0 0</pose>
    <link name="base_link">
      <inertial>
        <pose degrees="true">0 0 0 0 90 0</pose>
        <mass>0.05</mass>
        <inertia>
          <ixx>0.000126667</ixx>
          <ixy>0</ixy>
          <ixz>0</ixz>
          <iyy>0.000126667</iyy>
          <iyz>0</iyz>
          <izz>0.00009</izz>
        </inertia>
      </inertial>
      <collision name="collision">
        <pose degrees="true">0 0 0 0 90 0</pose>
        <geometry>
          <!-- <cylinder>
            <radius>0.05</radius>
            <length>0.140</length>
          </cylinder> -->
          <box>
            <size>0.1 0.1 0.140</size>
          </box>
        </geometry>
        <surface>
          <friction>
            <ode>
              <mu>1.0</mu>
              <mu2>1.0</mu2>
            </ode>
          </friction>
        </surface>
      </collision>
      <visual name="visual">
        <pose degrees="true">0 0 0 0 90 0</pose>
        <geometry>
          <cylinder>
            <radius>0.05</radius>
            <length>0.140</length>
          </cylinder>
        </geometry>
        <material>
          <ambient>0.5 0.5 0.5 1</ambient>
          <diffuse>0.5 0.5 0.5 1</diffuse>
          <specular>0.1 0.1 0.1 1</specular>
        </material>
      </visual>
      <sensor name="imu_sensor" type="imu">
        <pose degrees="true">0 0 0 180 0 0</pose>
        <always_on>1</always_on>
        <update_rate>1000.0</update_rate>
      </sensor>
    </link>

    <link name="fuselage_front_link">
      <pose>0.095 0 0 0 0 0</pose>
      <inertial>
        <pose degrees="true">0 0 0 0 90 0</pose>
        <mass>0.05</mass>
        <inertia>
          <ixx>5.54167E-05</ixx>
          <ixy>0</ixy>
          <ixz>0</ixz>
          <iyy>5.54167E-05</iyy>
          <iyz>0</iyz>
          <izz>0.00009</izz>
        </inertia>
      </inertial>
      <collision name="collision">
        <pose degrees="true">0 0 0 0 90 0</pose>
        <geometry>
          <cylinder>
            <radius>0.05</radius>
            <length>0.05</length>
          </cylinder>
        </geometry>
      </collision>
      <collision name="nose_cone_collision">
        <pose degrees="true">0.075 0 0 0 90 0</pose>
        <geometry>
          <cone>
            <radius>0.05</radius>
            <length>0.10</length>
          </cone>
        </geometry>
      </collision>
      <visual name="visual">
        <pose degrees="true">0 0 0 0 90 0</pose>
        <geometry>
          <cylinder>
            <radius>0.05</radius>
            <length>0.05</length>
          </cylinder>
        </geometry>
        <material>
          <ambient>0.5 0.5 0.5 1</ambient>
          <diffuse>0.5 0.5 0.5 1</diffuse>
          <specular>0.1 0.1 0.1 1</specular>
        </material>
      </visual>
      <visual name="nose_cone_visual">
        <pose degrees="true">0.075 0 0 0 90 0</pose>
        <geometry>
          <cone>
            <radius>0.05</radius>
            <length>0.10</length>
          </cone>
        </geometry>
        <material>
          <ambient>0.5 0.5 0.5 1</ambient>
          <diffuse>0.5 0.5 0.5 1</diffuse>
          <specular>0.1 0.1 0.1 1</specular>
        </material>
      </visual>
    </link>
    <joint name="fuselage_front_joint" type="revolute">
      <pose>-0.025 0 0 0 0 0</pose>
      <parent>base_link</parent>
      <child>fuselage_front_link</child>
      <axis>
        <limit>
          <lower>0</lower>
          <upper>0</upper>
        </limit>
        <xyz>0 0 1</xyz>
      </axis>
    </joint>

    <link name="fuselage_back_link">
      <pose>-0.095 0 0 0 0 0</pose>
      <inertial>
        <pose degrees="true">0 0 0 0 90 0</pose>
        <mass>0.05</mass>
        <inertia>
          <ixx>5.54167E-05</ixx>
          <ixy>0</ixy>
          <ixz>0</ixz>
          <iyy>5.54167E-05</iyy>
          <iyz>0</iyz>
          <izz>0.00009</izz>
        </inertia>
      </inertial>
      <collision name="collision">
        <pose degrees="true">0 0 0 0 90 0</pose>
        <geometry>
          <cylinder>
            <radius>0.05</radius>
            <length>0.05</length>
          </cylinder>
        </geometry>
      </collision>
      <visual name="visual">
        <pose degrees="true">0 0 0 0 90 0</pose>
        <geometry>
          <cylinder>
            <radius>0.05</radius>
            <length>0.05</length>
          </cylinder>
        </geometry>
        <material>
          <ambient>0.5 0.5 0.5 1</ambient>
          <diffuse>0.5 0.5 0.5 1</diffuse>
          <specular>0.1 0.1 0.1 1</specular>
        </material>
      </visual>
    </link>
    <joint name="fuselage_back_joint" type="revolute">
      <pose>0.025 0 0 0 0 0</pose>
      <parent>base_link</parent>
      <child>fuselage_back_link</child>
      <axis>
        <limit>
          <lower>0</lower>
          <upper>0</upper>
        </limit>
        <xyz>0 0 1</xyz>
      </axis>
    </joint>

    <link name="wing_front_left_link">
      <pose>0.0675 0.125 0 0 0 0</pose>
      <inertial>
        <mass>0.05</mass>
        <inertia>
          <ixx>9.41667E-05</ixx>
          <ixy>0</ixy>
          <ixz>0</ixz>
          <iyy>5.08333E-05</iyy>
          <iyz>0</iyz>
          <izz>0.000144167</izz>
        </inertia>
      </inertial>
      <collision name="collision">
        <geometry>
          <box>
            <size>0.110 0.150 0.010</size>
          </box>
        </geometry>
      </collision>
      <visual name="visual">
        <geometry>
          <box>
            <size>0.110 0.150 0.010</size>
          </box>
        </geometry>
        <material>
          <ambient>0.5 0.5 0.5 1</ambient>
          <diffuse>0.5 0.5 0.5 1</diffuse>
          <specular>0.1 0.1 0.1 1</specular>
        </material>
      </visual>
      <visual name="motor_visual">
        <pose degrees="true">0.05 0 0 0 90 0</pose>
        <geometry>
          <cylinder>
            <radius>0.012</radius>
            <length>0.026</length>
          </cylinder>
        </geometry>
        <material>
          <ambient>0 0 1 1</ambient>
          <diffuse>0 0 1 1</diffuse>
          <specular>0.1 0.1 0.1 1</specular>
        </material>
      </visual>
    </link>
    <joint name="wing_front_left_joint" type="revolute">
      <pose>0.0275 -0.075 0 0 0 0</pose>
      <parent>fuselage_front_link</parent>
      <child>wing_front_left_link</child>
      <axis>
        <limit>
          <lower>-1.57079632</lower>
          <upper>1.57079632</upper>
        </limit>
        <xyz>0 1 0</xyz>
      </axis>
    </joint>

    <link name="wing_front_right_link">
      <pose>0.0675 -0.125 0 0 0 0</pose>
      <inertial>
        <mass>0.05</mass>
        <inertia>
          <ixx>9.41667E-05</ixx>
          <ixy>0</ixy>
          <ixz>0</ixz>
          <iyy>5.08333E-05</iyy>
          <iyz>0</iyz>
          <izz>0.000144167</izz>
        </inertia>
      </inertial>
      <collision name="collision">
        <geometry>
          <box>
            <size>0.110 0.150 0.010</size>
          </box>
        </geometry>
      </collision>
      <visual name="visual">
        <geometry>
          <box>
            <size>0.110 0.150 0.010</size>
          </box>
        </geometry>
        <material>
          <ambient>0.5 0.5 0.5 1</ambient>
          <diffuse>0.5 0.5 0.5 1</diffuse>
          <specular>0.1 0.1 0.1 1</specular>
        </material>
      </visual>
      <visual name="motor_visual">
        <pose degrees="true">0.05 0 0 0 90 0</pose>
        <geometry>
          <cylinder>
            <radius>0.012</radius>
            <length>0.026</length>
          </cylinder>
        </geometry>
        <material>
          <ambient>0 0 1 1</ambient>
          <diffuse>0 0 1 1</diffuse>
          <specular>0.1 0.1 0.1 1</specular>
        </material>
      </visual>
    </link>
    <joint name="wing_front_right_joint" type="revolute">
      <pose>0.0275 0.075 0 0 0 0</pose>
      <parent>fuselage_front_link</parent>
      <child>wing_front_right_link</child>
      <axis>
        <limit>
          <lower>-1.57079632</lower>
          <upper>1.57079632</upper>
        </limit>
        <xyz>0 1 0</xyz>
      </axis>
    </joint>

    <link name="wing_back_left_link">
      <pose>-0.1225 0.125 0 0 0 0</pose>
      <inertial>
        <mass>0.05</mass>
        <inertia>
          <ixx>9.41667E-05</ixx>
          <ixy>0</ixy>
          <ixz>0</ixz>
          <iyy>5.08333E-05</iyy>
          <iyz>0</iyz>
          <izz>0.000144167</izz>
        </inertia>
      </inertial>
      <collision name="collision">
        <geometry>
          <box>
            <size>0.110 0.150 0.010</size>
          </box>
        </geometry>
      </collision>
      <visual name="visual">
        <geometry>
          <box>
            <size>0.110 0.150 0.010</size>
          </box>
        </geometry>
        <material>
          <ambient>0.5 0.5 0.5 1</ambient>
          <diffuse>0.5 0.5 0.5 1</diffuse>
          <specular>0.1 0.1 0.1 1</specular>
        </material>
      </visual>
      <visual name="motor_visual">
        <pose degrees="true">0.05 0 0 0 90 0</pose>
        <geometry>
          <cylinder>
            <radius>0.012</radius>
            <length>0.026</length>
          </cylinder>
        </geometry>
        <material>
          <ambient>0 0 1 1</ambient>
          <diffuse>0 0 1 1</diffuse>
          <specular>0.1 0.1 0.1 1</specular>
        </material>
      </visual>
    </link>
    <joint name="wing_back_left_joint" type="revolute">
      <pose>0.0275 -0.075 0 0 0 0</pose>
      <parent>fuselage_back_link</parent>
      <child>wing_back_left_link</child>
      <axis>
        <limit>
          <lower>-1.57079632</lower>
          <upper>1.57079632</upper>
        </limit>
        <xyz>0 1 0</xyz>
      </axis>
    </joint>

    <link name="wing_back_right_link">
      <pose>-0.1225 -0.125 0 0 0 0</pose>
      <inertial>
        <mass>0.05</mass>
        <inertia>
          <ixx>9.41667E-05</ixx>
          <ixy>0</ixy>
          <ixz>0</ixz>
          <iyy>5.08333E-05</iyy>
          <iyz>0</iyz>
          <izz>0.000144167</izz>
        </inertia>
      </inertial>
      <collision name="collision">
        <geometry>
          <box>
            <size>0.110 0.150 0.010</size>
          </box>
        </geometry>
      </collision>
      <visual name="visual">
        <geometry>
          <box>
            <size>0.110 0.150 0.010</size>
          </box>
        </geometry>
        <material>
          <ambient>0.5 0.5 0.5 1</ambient>
          <diffuse>0.5 0.5 0.5 1</diffuse>
          <specular>0.1 0.1 0.1 1</specular>
        </material>
      </visual>
      <visual name="motor_visual">
        <pose degrees="true">0.05 0 0 0 90 0</pose>
        <geometry>
          <cylinder>
            <radius>0.012</radius>
            <length>0.026</length>
          </cylinder>
        </geometry>
        <material>
          <ambient>0 0 1 1</ambient>
          <diffuse>0 0 1 1</diffuse>
          <specular>0.1 0.1 0.1 1</specular>
        </material>
      </visual>
    </link>
    <joint name="wing_back_right_joint" type="revolute">
      <pose>0.0275 0.075 0 0 0 0</pose>
      <parent>fuselage_back_link</parent>
      <child>wing_back_right_link</child>
      <axis>
        <limit>
          <lower>-1.57079632</lower>
          <upper>1.57079632</upper>
        </limit>
        <xyz>0 1 0</xyz>
      </axis>
    </joint>

    <link name="motor_front_left_link">
      <pose degrees="true">0.1225 0.125 0 0 90 0</pose>
      <inertial>
        <mass>0.05</mass>
        <inertia>
          <ixx>4.92917E-06</ixx>
          <ixy>0</ixy>
          <ixz>0</ixz>
          <iyy>4.92917E-06</iyy>
          <iyz>0</iyz>
          <izz>0.000004225</izz>
        </inertia>
      </inertial>
      <collision name="collision">
        <geometry>
          <cylinder>
            <radius>0.013</radius>
            <length>0.026</length>
          </cylinder>
        </geometry>
      </collision>
      <visual name="visual">
        <geometry>
          <cylinder>
            <radius>0.013</radius>
            <length>0.026</length>
          </cylinder>
        </geometry>
        <material>
          <ambient>1 0 0 1</ambient>
          <diffuse>1 0 0 1</diffuse>
          <specular>0.1 0.1 0.1 1</specular>
        </material>
      </visual>
      <visual name="prop_blade_1_visual">
        <pose degrees="true">0.030625 0 0.015 0 0 0</pose>
        <geometry>
          <box>
            <size>0.06125 0.01 0.002</size>
          </box>
        </geometry>
        <material>
          <ambient>0 1 0 1</ambient>
          <diffuse>0 1 0 1</diffuse>
          <specular>0.1 0.1 0.1 1</specular>
        </material>
      </visual>
      <visual name="prop_blade_2_visual">
        <pose degrees="true">-0.0153125 0.026522027990898433 0.015 0 0 120</pose>
        <geometry>
          <box>
            <size>0.06125 0.01 0.002</size>
          </box>
        </geometry>
        <material>
          <ambient>0 1 0 1</ambient>
          <diffuse>0 1 0 1</diffuse>
          <specular>0.1 0.1 0.1 1</specular>
        </material>
      </visual>
      <visual name="prop_blade_3_visual">
        <pose degrees="true">-0.0153125 -0.026522027990898433 0.015 0 0 240</pose>
        <geometry>
          <box>
            <size>0.06125 0.01 0.002</size>
          </box>
        </geometry>
        <material>
          <ambient>0 1 0 1</ambient>
          <diffuse>0 1 0 1</diffuse>
          <specular>0.1 0.1 0.1 1</specular>
        </material>
      </visual>
    </link>
    <joint name="motor_front_left_joint" type="revolute">
      <pose>0 0 0 0 0 0</pose>
      <parent>wing_front_left_link</parent>
      <child>motor_front_left_link</child>
      <axis>
        <limit>
          <lower>-1.0e16</lower>
          <upper>1.0e16</upper>
        </limit>
        <xyz>0 0 1</xyz>
      </axis>
    </joint>

    <link name="motor_front_right_link">
      <pose degrees="true">0.1225 -0.125 0 0 90 0</pose>
      <inertial>
        <mass>0.05</mass>
        <inertia>
          <ixx>4.92917E-06</ixx>
          <ixy>0</ixy>
          <ixz>0</ixz>
          <iyy>4.92917E-06</iyy>
          <iyz>0</iyz>
          <izz>0.000004225</izz>
        </inertia>
      </inertial>
      <collision name="collision">
        <geometry>
          <cylinder>
            <radius>0.013</radius>
            <length>0.026</length>
          </cylinder>
        </geometry>
      </collision>
      <visual name="visual">
        <geometry>
          <cylinder>
            <radius>0.013</radius>
            <length>0.026</length>
          </cylinder>
        </geometry>
        <material>
          <ambient>1 0 0 1</ambient>
          <diffuse>1 0 0 1</diffuse>
          <specular>0.1 0.1 0.1 1</specular>
        </material>
      </visual>
      <visual name="prop_blade_1_visual">
        <pose degrees="true">0.030625 0 0.015 0 0 0</pose>
        <geometry>
          <box>
            <size>0.06125 0.01 0.002</size>
          </box>
        </geometry>
        <material>
          <ambient>0 1 0 1</ambient>
          <diffuse>0 1 0 1</diffuse>
          <specular>0.1 0.1 0.1 1</specular>
        </material>
      </visual>
      <visual name="prop_blade_2_visual">
        <pose degrees="true">-0.0153125 0.026522027990898433 0.015 0 0 120</pose>
        <geometry>
          <box>
            <size>0.06125 0.01 0.002</size>
          </box>
        </geometry>
        <material>
          <ambient>0 1 0 1</ambient>
          <diffuse>0 1 0 1</diffuse>
          <specular>0.1 0.1 0.1 1</specular>
        </material>
      </visual>
      <visual name="prop_blade_3_visual">
        <pose degrees="true">-0.0153125 -0.026522027990898433 0.015 0 0 240</pose>
        <geometry>
          <box>
            <size>0.06125 0.01 0.002</size>
          </box>
        </geometry>
        <material>
          <ambient>0 1 0 1</ambient>
          <diffuse>0 1 0 1</diffuse>
          <specular>0.1 0.1 0.1 1</specular>
        </material>
      </visual>
    </link>
    <joint name="motor_front_right_joint" type="revolute">
      <pose>0 0 0 0 0 0</pose>
      <parent>wing_front_right_link</parent>
      <child>motor_front_right_link</child>
      <axis>
        <limit>
          <lower>-1.0e16</lower>
          <upper>1.0e16</upper>
        </limit>
        <xyz>0 0 1</xyz>
      </axis>
    </joint>

    <link name="motor_back_left_link">
      <pose degrees="true">-0.0675 0.125 0 0 90 0</pose>
      <inertial>
        <mass>0.05</mass>
        <inertia>
          <ixx>4.92917E-06</ixx>
          <ixy>0</ixy>
          <ixz>0</ixz>
          <iyy>4.92917E-06</iyy>
          <iyz>0</iyz>
          <izz>0.000004225</izz>
        </inertia>
      </inertial>
      <collision name="collision">
        <geometry>
          <cylinder>
            <radius>0.013</radius>
            <length>0.026</length>
          </cylinder>
        </geometry>
      </collision>
      <visual name="visual">
        <geometry>
          <cylinder>
            <radius>0.013</radius>
            <length>0.026</length>
          </cylinder>
        </geometry>
        <material>
          <ambient>1 0 0 1</ambient>
          <diffuse>1 0 0 1</diffuse>
          <specular>0.1 0.1 0.1 1</specular>
        </material>
      </visual>
      <visual name="prop_blade_1_visual">
        <pose degrees="true">0.030625 0 0.015 0 0 0</pose>
        <geometry>
          <box>
            <size>0.06125 0.01 0.002</size>
          </box>
        </geometry>
        <material>
          <ambient>0 1 0 1</ambient>
          <diffuse>0 1 0 1</diffuse>
          <specular>0.1 0.1 0.1 1</specular>
        </material>
      </visual>
      <visual name="prop_blade_2_visual">
        <pose degrees="true">-0.0153125 0.026522027990898433 0.015 0 0 120</pose>
        <geometry>
          <box>
            <size>0.06125 0.01 0.002</size>
          </box>
        </geometry>
        <material>
          <ambient>0 1 0 1</ambient>
          <diffuse>0 1 0 1</diffuse>
          <specular>0.1 0.1 0.1 1</specular>
        </material>
      </visual>
      <visual name="prop_blade_3_visual">
        <pose degrees="true">-0.0153125 -0.026522027990898433 0.015 0 0 240</pose>
        <geometry>
          <box>
            <size>0.06125 0.01 0.002</size>
          </box>
        </geometry>
        <material>
          <ambient>0 1 0 1</ambient>
          <diffuse>0 1 0 1</diffuse>
          <specular>0.1 0.1 0.1 1</specular>
        </material>
      </visual>
    </link>
    <joint name="motor_back_left_joint" type="revolute">
      <pose>0 0 0 0 0 0</pose>
      <parent>wing_back_left_link</parent>
      <child>motor_back_left_link</child>
      <axis>
        <limit>
          <lower>-1.0e16</lower>
          <upper>1.0e16</upper>
        </limit>
        <xyz>0 0 1</xyz>
      </axis>
    </joint>

    <link name="motor_back_right_link">
      <pose degrees="true">-0.0675 -0.125 0 0 90 0</pose>
      <inertial>
        <mass>0.05</mass>
        <inertia>
          <ixx>4.92917E-06</ixx>
          <ixy>0</ixy>
          <ixz>0</ixz>
          <iyy>4.92917E-06</iyy>
          <iyz>0</iyz>
          <izz>0.000004225</izz>
        </inertia>
      </inertial>
      <collision name="collision">
        <geometry>
          <cylinder>
            <radius>0.013</radius>
            <length>0.026</length>
          </cylinder>
        </geometry>
      </collision>
      <visual name="visual">
        <geometry>
          <cylinder>
            <radius>0.013</radius>
            <length>0.026</length>
          </cylinder>
        </geometry>
        <material>
          <ambient>1 0 0 1</ambient>
          <diffuse>1 0 0 1</diffuse>
          <specular>0.1 0.1 0.1 1</specular>
        </material>
      </visual>
      <visual name="prop_blade_1_visual">
        <pose degrees="true">0.030625 0 0.015 0 0 0</pose>
        <geometry>
          <box>
            <size>0.06125 0.01 0.002</size>
          </box>
        </geometry>
        <material>
          <ambient>0 1 0 1</ambient>
          <diffuse>0 1 0 1</diffuse>
          <specular>0.1 0.1 0.1 1</specular>
        </material>
      </visual>
      <visual name="prop_blade_2_visual">
        <pose degrees="true">-0.0153125 0.026522027990898433 0.015 0 0 120</pose>
        <geometry>
          <box>
            <size>0.06125 0.01 0.002</size>
          </box>
        </geometry>
        <material>
          <ambient>0 1 0 1</ambient>
          <diffuse>0 1 0 1</diffuse>
          <specular>0.1 0.1 0.1 1</specular>
        </material>
      </visual>
      <visual name="prop_blade_3_visual">
        <pose degrees="true">-0.0153125 -0.026522027990898433 0.015 0 0 240</pose>
        <geometry>
          <box>
            <size>0.06125 0.01 0.002</size>
          </box>
        </geometry>
        <material>
          <ambient>0 1 0 1</ambient>
          <diffuse>0 1 0 1</diffuse>
          <specular>0.1 0.1 0.1 1</specular>
        </material>
      </visual>
    </link>
    <joint name="motor_back_right_joint" type="revolute">
      <pose>0 0 0 0 0 0</pose>
      <parent>wing_back_right_link</parent>
      <child>motor_back_right_link</child>
      <axis>
        <limit>
          <lower>-1.0e16</lower>
          <upper>1.0e16</upper>
        </limit>
        <xyz>0 0 1</xyz>
      </axis>
    </joint>

    <!-- plugins -->
    <plugin name="gz::sim::systems::JointStatePublisher"
        filename="gz-sim-joint-state-publisher-system">
    </plugin>

    <plugin name="gz::sim::systems::JointPositionController"
        filename="gz-sim-joint-position-controller-system">
      <joint_name>wing_front_left_joint</joint_name>
      <topic>/model/morphing_quad/joint/wing_front_left_joint/cmd_pos</topic>
      <initial_position>-1.57079632</initial_position>
      <p_gain>0.4</p_gain>
      <i_gain>0</i_gain>
      <d_gain>1.0e-2</d_gain>
      <i_max>1</i_max>
      <i_min>-1</i_min>
      <cmd_max>1.0e4</cmd_max>
      <cmd_min>-1.0e4</cmd_min>
    </plugin>
    <plugin name="gz::sim::systems::JointPositionController"
        filename="gz-sim-joint-position-controller-system">
      <joint_name>wing_front_right_joint</joint_name>
      <topic>/model/morphing_quad/joint/wing_front_right_joint/cmd_pos</topic>
      <initial_position>-1.57079632</initial_position>
      <p_gain>0.4</p_gain>
      <i_gain>0</i_gain>
      <d_gain>1.0e-2</d_gain>
      <i_max>1</i_max>
      <i_min>-1</i_min>
      <cmd_max>1.0e4</cmd_max>
      <cmd_min>-1.0e4</cmd_min>
    </plugin>
    <plugin name="gz::sim::systems::JointPositionController"
        filename="gz-sim-joint-position-controller-system">
      <joint_name>wing_back_left_joint</joint_name>
      <topic>/model/morphing_quad/joint/wing_back_left_joint/cmd_pos</topic>
      <initial_position>-1.57079632</initial_position>
      <p_gain>0.4</p_gain>
      <i_gain>0</i_gain>
      <d_gain>1.0e-2</d_gain>
      <i_max>1</i_max>
      <i_min>-1</i_min>
      <cmd_max>1.0e4</cmd_max>
      <cmd_min>-1.0e4</cmd_min>
    </plugin>
    <plugin name="gz::sim::systems::JointPositionController"
        filename="gz-sim-joint-position-controller-system">
      <joint_name>wing_back_right_joint</joint_name>
      <topic>/model/morphing_quad/joint/wing_back_right_joint/cmd_pos</topic>
      <initial_position>-1.57079632</initial_position>
      <p_gain>0.4</p_gain>
      <i_gain>0</i_gain>
      <d_gain>1.0e-2</d_gain>
      <i_max>1</i_max>
      <i_min>-1</i_min>
      <cmd_max>1.0e4</cmd_max>
      <cmd_min>-1.0e4</cmd_min>
    </plugin>

    <plugin name="gz::sim::systems::JointController"
      filename="gz-sim-joint-controller-system">
      <joint_name>motor_front_left_joint</joint_name>
      <use_force_commands>1</use_force_commands>
      <topic>/model/morphing_quad/joint/motor_front_left_joint/cmd_vel</topic>
      <initial_velocity>0.0</initial_velocity>
      <p_gain>0.001</p_gain>
      <d_gain>1.0e-8</d_gain>
      <cmd_max>1.0e3</cmd_max>
      <cmd_min>-1.0e3</cmd_min>
    </plugin>
    <plugin name="gz::sim::systems::JointController"
      filename="gz-sim-joint-controller-system">
      <joint_name>motor_front_right_joint</joint_name>
      <use_force_commands>1</use_force_commands>
      <topic>/model/morphing_quad/joint/motor_front_right_joint/cmd_vel</topic>
      <initial_velocity>0.0</initial_velocity>
      <p_gain>0.001</p_gain>
      <d_gain>1.0e-8</d_gain>
      <cmd_max>1.0e3</cmd_max>
      <cmd_min>-1.0e3</cmd_min>
    </plugin>
    <plugin name="gz::sim::systems::JointController"
      filename="gz-sim-joint-controller-system">
      <joint_name>motor_back_left_joint</joint_name>
      <use_force_commands>1</use_force_commands>
      <topic>/model/morphing_quad/joint/motor_back_left_joint/cmd_vel</topic>
      <initial_velocity>0.0</initial_velocity>
      <p_gain>0.001</p_gain>
      <d_gain>1.0e-8</d_gain>
      <cmd_max>1.0e3</cmd_max>
      <cmd_min>-1.0e3</cmd_min>
    </plugin>
    <plugin name="gz::sim::systems::JointController"
      filename="gz-sim-joint-controller-system">
      <joint_name>motor_back_right_joint</joint_name>
      <use_force_commands>1</use_force_commands>
      <topic>/model/morphing_quad/joint/motor_back_right_joint/cmd_vel</topic>
      <initial_velocity>0.0</initial_velocity>
      <p_gain>0.001</p_gain>
      <d_gain>1.0e-8</d_gain>
      <cmd_max>1.0e3</cmd_max>
      <cmd_min>-1.0e3</cmd_min>
    </plugin>

  </model>
</sdf>
