<?xml version="1.0"?>
<!--
  Dimensions

  Prop  : 5 inch
  Motor : model:  tbd
          mass:   tbd
          size:   tbd
          thrust: tbd
  ESC   : tbd
  Servo : model:  tbd
          mass:   tbd
          torque: tbd
          size:   tbd

  Wing:   span:   0.150m
          chord:  0.110m

-->
<sdf version="1.9"> 
  <model name="morphing_quad">
    <pose>0 0 0 0 0 0</pose>
    <link name="base_link">
      <inertial>
        <pose degrees="true">0 0 0 0 90 0</pose>
        <mass>0.05</mass>
        <inertia>
          <ixx>0.000126667</ixx>
          <ixy>0</ixy>
          <ixz>0</ixz>
          <iyy>0.000126667</iyy>
          <iyz>0</iyz>
          <izz>0.00009</izz>
        </inertia>
      </inertial>
      <collision name="collision">
        <pose degrees="true">0 0 0 0 90 0</pose>
        <geometry>
          <!-- <cylinder>
            <radius>0.05</radius>
            <length>0.140</length>
          </cylinder> -->
          <box>
            <size>0.1 0.1 0.140</size>
          </box>
        </geometry>
        <surface>
          <friction>
            <ode>
              <mu>1.0</mu>
              <mu2>1.0</mu2>
            </ode>
          </friction>
        </surface>
      </collision>
      <visual name="visual">
        <pose degrees="true">0 0 0 0 90 0</pose>
        <geometry>
          <cylinder>
            <radius>0.05</radius>
            <length>0.140</length>
          </cylinder>
        </geometry>
        <material>
          <ambient>0.5 0.5 0.5 1</ambient>
          <diffuse>0.5 0.5 0.5 1</diffuse>
          <specular>0.1 0.1 0.1 1</specular>
        </material>
      </visual>
    </link>

    <link name="fuselage_front_link">
      <pose>0.095 0 0 0 0 0</pose>
      <inertial>
        <pose degrees="true">0 0 0 0 90 0</pose>
        <mass>0.05</mass>
        <inertia>
          <ixx>5.54167E-05</ixx>
          <ixy>0</ixy>
          <ixz>0</ixz>
          <iyy>5.54167E-05</iyy>
          <iyz>0</iyz>
          <izz>0.00009</izz>
        </inertia>
      </inertial>
      <collision name="collision">
        <pose degrees="true">0 0 0 0 90 0</pose>
        <geometry>
          <cylinder>
            <radius>0.05</radius>
            <length>0.05</length>
          </cylinder>
        </geometry>
      </collision>
      <collision name="nose_cone_collision">
        <pose degrees="true">0.075 0 0 0 90 0</pose>
        <geometry>
          <cone>
            <radius>0.05</radius>
            <length>0.10</length>
          </cone>
        </geometry>
      </collision>
      <visual name="visual">
        <pose degrees="true">0 0 0 0 90 0</pose>
        <geometry>
          <cylinder>
            <radius>0.05</radius>
            <length>0.05</length>
          </cylinder>
        </geometry>
        <material>
          <ambient>0.5 0.5 0.5 1</ambient>
          <diffuse>0.5 0.5 0.5 1</diffuse>
          <specular>0.1 0.1 0.1 1</specular>
        </material>
      </visual>
      <visual name="nose_cone_visual">
        <pose degrees="true">0.075 0 0 0 90 0</pose>
        <geometry>
          <cone>
            <radius>0.05</radius>
            <length>0.10</length>
          </cone>
        </geometry>
        <material>
          <ambient>0.5 0.5 0.5 1</ambient>
          <diffuse>0.5 0.5 0.5 1</diffuse>
          <specular>0.1 0.1 0.1 1</specular>
        </material>
      </visual>
    </link>
    <joint name="fuselage_front_joint" type="revolute">
      <pose>-0.025 0 0 0 0 0</pose>
      <parent>base_link</parent>
      <child>fuselage_front_link</child>
      <axis>
        <limit>
          <lower>0</lower>
          <upper>0</upper>
        </limit>
        <xyz>0 0 1</xyz>
      </axis>
    </joint>

    <link name="fuselage_back_link">
      <pose>-0.095 0 0 0 0 0</pose>
      <inertial>
        <pose degrees="true">0 0 0 0 90 0</pose>
        <mass>0.05</mass>
        <inertia>
          <ixx>5.54167E-05</ixx>
          <ixy>0</ixy>
          <ixz>0</ixz>
          <iyy>5.54167E-05</iyy>
          <iyz>0</iyz>
          <izz>0.00009</izz>
        </inertia>
      </inertial>
      <collision name="collision">
        <pose degrees="true">0 0 0 0 90 0</pose>
        <geometry>
          <cylinder>
            <radius>0.05</radius>
            <length>0.05</length>
          </cylinder>
        </geometry>
      </collision>
      <visual name="visual">
        <pose degrees="true">0 0 0 0 90 0</pose>
        <geometry>
          <cylinder>
            <radius>0.05</radius>
            <length>0.05</length>
          </cylinder>
        </geometry>
        <material>
          <ambient>0.5 0.5 0.5 1</ambient>
          <diffuse>0.5 0.5 0.5 1</diffuse>
          <specular>0.1 0.1 0.1 1</specular>
        </material>
      </visual>
    </link>
    <joint name="fuselage_back_joint" type="revolute">
      <pose>0.025 0 0 0 0 0</pose>
      <parent>base_link</parent>
      <child>fuselage_back_link</child>
      <axis>
        <limit>
          <lower>0</lower>
          <upper>0</upper>
        </limit>
        <xyz>0 0 1</xyz>
      </axis>
    </joint>

    <link name="wing_front_left_link">
      <pose>0.0675 0.125 0 0 0 0</pose>
      <inertial>
        <mass>0.05</mass>
        <inertia>
          <ixx>9.41667E-05</ixx>
          <ixy>0</ixy>
          <ixz>0</ixz>
          <iyy>5.08333E-05</iyy>
          <iyz>0</iyz>
          <izz>0.000144167</izz>
        </inertia>
      </inertial>
      <collision name="collision">
        <geometry>
          <box>
            <size>0.110 0.150 0.010</size>
          </box>
        </geometry>
      </collision>
      <visual name="visual">
        <geometry>
          <box>
            <size>0.110 0.150 0.010</size>
          </box>
        </geometry>
        <material>
          <ambient>0.5 0.5 0.5 1</ambient>
          <diffuse>0.5 0.5 0.5 1</diffuse>
          <specular>0.1 0.1 0.1 1</specular>
        </material>
      </visual>
    </link>
    <joint name="wing_front_left_joint" type="revolute">
      <pose>0.0275 -0.075 0 0 0 0</pose>
      <parent>fuselage_front_link</parent>
      <child>wing_front_left_link</child>
      <axis>
        <limit>
          <lower>-1.57079632</lower>
          <upper>1.57079632</upper>
        </limit>
        <xyz>0 1 0</xyz>
      </axis>
    </joint>



  </model>
</sdf>
