<?xml version="1.0"?>
<!--
  Dimensions
  ==========

  Prop  : 5 inch
  Motor : model:  tbd
          mass:   tbd
          size:   tbd
          thrust: tbd
  ESC   : tbd
  Servo : model:  tbd
          mass:   tbd
          torque: tbd
          size:   tbd

  Wing:   span:   0.150m
          chord:  0.110m


  Wing joint position controllers
  ===============================

  gz topic -t /model/morphing_quad/joint/wing_front_left_joint/cmd_pos -m gz.msgs.Double -p "data: -1.57"

  Motor joint velocity controllers
  ================================

  gz topic -t /model/morphing_quad/joint/motor_front_left_joint/cmd_vel -m gz.msgs.Double -p "data: -1.57"

  ArduPilot parameters
  ====================

  The vehicle is run as an X-frame quadcopter.
  
  For testing the wing tilt servo outputs use the outputs of RC6 and RC7. 

  FRAME_TYPE       1.000000 0.000000 # X (DEFAULT: Plus)
  SERVO1_MIN       1000.000000 1100.000000
  SERVO1_MAX       2000.000000 1900.000000
  SERVO2_MIN       1000.000000 1100.000000
  SERVO2_MAX       2000.000000 1900.000000
  SERVO3_MIN       1000.000000 1100.000000
  SERVO3_MAX       2000.000000 1900.000000
  SERVO4_MIN       1000.000000 1100.000000
  SERVO4_MAX       2000.000000 1900.000000
  SERVO6_MIN       1000.000000 1100.000000
  SERVO6_MAX       2000.000000 1900.000000
  SERVO6_FUNCTION  56.000000 0.000000 # RCIN6 (DEFAULT: Disabled)
  SERVO7_MIN       1000.000000 1100.000000
  SERVO7_MAX       2000.000000 1900.000000
  SERVO7_FUNCTION  57.000000 0.000000 # RCIN7 (DEFAULT: Disabled)

-->
<sdf version="1.9"> 
  <model name="morphing_quad">
    <pose>0 0 0 0 0 0</pose>
    <link name="base_link">
      <inertial>
        <pose degrees="true">0 0 0 0 90 0</pose>
        <mass>0.3</mass>
        <inertia>
          <ixx>0.0006775</ixx>
          <ixy>0</ixy>
          <ixz>0</ixz>
          <iyy>0.0006775</iyy>
          <iyz>0</iyz>
          <izz>0.000375</izz>
        </inertia>
      </inertial>
      <collision name="collision">
        <pose degrees="true">0 0 0 0 90 0</pose>
        <geometry>
          <!-- <cylinder>
            <radius>0.05</radius>
            <length>0.140</length>
          </cylinder> -->
          <box>
            <size>0.1 0.1 0.140</size>
          </box>
        </geometry>
        <surface>
          <friction>
            <ode>
              <mu>1.0</mu>
              <mu2>1.0</mu2>
            </ode>
          </friction>
        </surface>
      </collision>
      <visual name="visual">
        <pose degrees="true">0 0 0 0 90 0</pose>
        <geometry>
          <cylinder>
            <radius>0.05</radius>
            <length>0.140</length>
          </cylinder>
        </geometry>
        <material>
          <ambient>0.9 0.9 0.9 1</ambient>
          <diffuse>0.9 0.9 0.9 1</diffuse>
          <specular>0.1 0.1 0.1 1</specular>
        </material>
      </visual>
      <sensor name="imu_sensor" type="imu">
        <pose degrees="true">0 0 0 180 0 0</pose>
        <always_on>1</always_on>
        <update_rate>1000.0</update_rate>
      </sensor>
    </link>

    <link name="fuselage_front_link">
      <pose>0.095 0 0 0 0 0</pose>
      <inertial>
        <pose degrees="true">0 0 0 0 90 0</pose>
        <mass>0.05</mass>
        <inertia>
          <ixx>5.54167E-05</ixx>
          <ixy>0</ixy>
          <ixz>0</ixz>
          <iyy>5.54167E-05</iyy>
          <iyz>0</iyz>
          <izz>0.00009</izz>
        </inertia>
      </inertial>
      <collision name="collision">
        <pose degrees="true">0 0 0 0 90 0</pose>
        <geometry>
          <cylinder>
            <radius>0.05</radius>
            <length>0.05</length>
          </cylinder>
        </geometry>
      </collision>
      <collision name="nose_cone_collision">
        <pose degrees="true">0.075 0 0 0 90 0</pose>
        <geometry>
          <cone>
            <radius>0.05</radius>
            <length>0.10</length>
          </cone>
        </geometry>
      </collision>
      <visual name="visual">
        <pose degrees="true">0 0 0 0 90 0</pose>
        <geometry>
          <cylinder>
            <radius>0.05</radius>
            <length>0.05</length>
          </cylinder>
        </geometry>
        <material>
          <ambient>0.5 0.5 0.5 1</ambient>
          <diffuse>0.5 0.5 0.5 1</diffuse>
          <specular>0.1 0.1 0.1 1</specular>
        </material>
      </visual>
      <visual name="nose_cone_visual">
        <pose degrees="true">0.075 0 0 0 90 0</pose>
        <geometry>
          <cone>
            <radius>0.05</radius>
            <length>0.10</length>
          </cone>
        </geometry>
        <material>
          <ambient>1 0 0 1</ambient>
          <diffuse>1 0 0 1</diffuse>
          <specular>0.1 0.1 0.1 1</specular>
        </material>
      </visual>
    </link>
    <joint name="fuselage_front_joint" type="revolute">
      <pose>-0.025 0 0 0 0 0</pose>
      <parent>base_link</parent>
      <child>fuselage_front_link</child>
      <axis>
        <xyz>0 0 1</xyz>
        <limit>
          <lower>0</lower>
          <upper>0</upper>
        </limit>
        <dynamics>
          <damping>0.1</damping>
        </dynamics>
      </axis>
    </joint>

    <link name="fuselage_back_link">
      <pose>-0.095 0 0 0 0 0</pose>
      <inertial>
        <pose degrees="true">0 0 0 0 90 0</pose>
        <mass>0.05</mass>
        <inertia>
          <ixx>5.54167E-05</ixx>
          <ixy>0</ixy>
          <ixz>0</ixz>
          <iyy>5.54167E-05</iyy>
          <iyz>0</iyz>
          <izz>0.00009</izz>
        </inertia>
      </inertial>
      <collision name="collision">
        <pose degrees="true">0 0 0 0 90 0</pose>
        <geometry>
          <cylinder>
            <radius>0.05</radius>
            <length>0.05</length>
          </cylinder>
        </geometry>
      </collision>
      <visual name="visual">
        <pose degrees="true">0 0 0 0 90 0</pose>
        <geometry>
          <cylinder>
            <radius>0.05</radius>
            <length>0.05</length>
          </cylinder>
        </geometry>
        <material>
          <ambient>0.5 0.5 0.5 1</ambient>
          <diffuse>0.5 0.5 0.5 1</diffuse>
          <specular>0.1 0.1 0.1 1</specular>
        </material>
      </visual>
    </link>
    <joint name="fuselage_back_joint" type="revolute">
      <pose>0.025 0 0 0 0 0</pose>
      <parent>base_link</parent>
      <child>fuselage_back_link</child>
      <axis>
        <xyz>0 0 1</xyz>
        <limit>
          <lower>0</lower>
          <upper>0</upper>
        </limit>
        <dynamics>
          <damping>0.1</damping>
        </dynamics>
      </axis>
    </joint>

    <link name="wing_front_left_link">
      <pose>0.0675 0.125 0 0 0 0</pose>
      <inertial>
        <mass>0.025</mass>
        <inertia>
          <ixx>4.70833E-05</ixx>
          <ixy>0</ixy>
          <ixz>0</ixz>
          <iyy>2.54167E-05</iyy>
          <iyz>0</iyz>
          <izz>7.20833E-05</izz>
        </inertia>
      </inertial>
      <collision name="collision">
        <geometry>
          <box>
            <size>0.110 0.150 0.010</size>
          </box>
        </geometry>
      </collision>
      <visual name="visual">
        <geometry>
          <box>
            <size>0.110 0.150 0.010</size>
          </box>
        </geometry>
        <material>
          <ambient>0.9 0.9 0.9 1</ambient>
          <diffuse>0.9 0.9 0.9 1</diffuse>
          <specular>0.1 0.1 0.1 1</specular>
        </material>
      </visual>
      <visual name="motor_visual">
        <pose degrees="true">0.05 0 0 0 90 0</pose>
        <geometry>
          <cylinder>
            <radius>0.012</radius>
            <length>0.026</length>
          </cylinder>
        </geometry>
        <material>
          <ambient>0 0 1 1</ambient>
          <diffuse>0 0 1 1</diffuse>
          <specular>0.1 0.1 0.1 1</specular>
        </material>
      </visual>
    </link>
    <joint name="wing_front_left_joint" type="revolute">
      <pose>0.0275 -0.075 0 0 0 0</pose>
      <parent>fuselage_front_link</parent>
      <child>wing_front_left_link</child>
      <axis>
        <xyz>0 1 0</xyz>
        <limit>
          <lower>-1.57079632</lower>
          <upper>1.57079632</upper>
        </limit>
        <dynamics>
          <damping>0.01</damping>
        </dynamics>
      </axis>
    </joint>

    <link name="wing_front_right_link">
      <pose>0.0675 -0.125 0 0 0 0</pose>
      <inertial>
        <mass>0.025</mass>
        <inertia>
          <ixx>4.70833E-05</ixx>
          <ixy>0</ixy>
          <ixz>0</ixz>
          <iyy>2.54167E-05</iyy>
          <iyz>0</iyz>
          <izz>7.20833E-05</izz>
        </inertia>
      </inertial>
      <collision name="collision">
        <geometry>
          <box>
            <size>0.110 0.150 0.010</size>
          </box>
        </geometry>
      </collision>
      <visual name="visual">
        <geometry>
          <box>
            <size>0.110 0.150 0.010</size>
          </box>
        </geometry>
        <material>
          <ambient>0.9 0.9 0.9 1</ambient>
          <diffuse>0.9 0.9 0.9 1</diffuse>
          <specular>0.1 0.1 0.1 1</specular>
        </material>
      </visual>
      <visual name="motor_visual">
        <pose degrees="true">0.05 0 0 0 90 0</pose>
        <geometry>
          <cylinder>
            <radius>0.012</radius>
            <length>0.026</length>
          </cylinder>
        </geometry>
        <material>
          <ambient>0 0 1 1</ambient>
          <diffuse>0 0 1 1</diffuse>
          <specular>0.1 0.1 0.1 1</specular>
        </material>
      </visual>
    </link>
    <joint name="wing_front_right_joint" type="revolute">
      <pose>0.0275 0.075 0 0 0 0</pose>
      <parent>fuselage_front_link</parent>
      <child>wing_front_right_link</child>
      <axis>
        <xyz>0 1 0</xyz>
        <limit>
          <lower>-1.57079632</lower>
          <upper>1.57079632</upper>
        </limit>
        <dynamics>
          <damping>0.01</damping>
        </dynamics>
      </axis>
    </joint>

    <link name="wing_back_left_link">
      <pose>-0.1225 0.125 0 0 0 0</pose>
      <inertial>
        <mass>0.025</mass>
        <inertia>
          <ixx>4.70833E-05</ixx>
          <ixy>0</ixy>
          <ixz>0</ixz>
          <iyy>2.54167E-05</iyy>
          <iyz>0</iyz>
          <izz>7.20833E-05</izz>
        </inertia>
      </inertial>
      <collision name="collision">
        <geometry>
          <box>
            <size>0.110 0.150 0.010</size>
          </box>
        </geometry>
      </collision>
      <visual name="visual">
        <geometry>
          <box>
            <size>0.110 0.150 0.010</size>
          </box>
        </geometry>
        <material>
          <ambient>0.9 0.9 0.9 1</ambient>
          <diffuse>0.9 0.9 0.9 1</diffuse>
          <specular>0.1 0.1 0.1 1</specular>
        </material>
      </visual>
      <visual name="motor_visual">
        <pose degrees="true">0.05 0 0 0 90 0</pose>
        <geometry>
          <cylinder>
            <radius>0.012</radius>
            <length>0.026</length>
          </cylinder>
        </geometry>
        <material>
          <ambient>0 0 1 1</ambient>
          <diffuse>0 0 1 1</diffuse>
          <specular>0.1 0.1 0.1 1</specular>
        </material>
      </visual>
    </link>
    <joint name="wing_back_left_joint" type="revolute">
      <pose>0.0275 -0.075 0 0 0 0</pose>
      <parent>fuselage_back_link</parent>
      <child>wing_back_left_link</child>
      <axis>
        <xyz>0 1 0</xyz>
        <limit>
          <lower>-1.57079632</lower>
          <upper>1.57079632</upper>
        </limit>
        <dynamics>
          <damping>0.01</damping>
        </dynamics>
      </axis>
    </joint>

    <link name="wing_back_right_link">
      <pose>-0.1225 -0.125 0 0 0 0</pose>
      <inertial>
        <mass>0.025</mass>
        <inertia>
          <ixx>4.70833E-05</ixx>
          <ixy>0</ixy>
          <ixz>0</ixz>
          <iyy>2.54167E-05</iyy>
          <iyz>0</iyz>
          <izz>7.20833E-05</izz>
        </inertia>
      </inertial>
      <collision name="collision">
        <geometry>
          <box>
            <size>0.110 0.150 0.010</size>
          </box>
        </geometry>
      </collision>
      <visual name="visual">
        <geometry>
          <box>
            <size>0.110 0.150 0.010</size>
          </box>
        </geometry>
        <material>
          <ambient>0.9 0.9 0.9 1</ambient>
          <diffuse>0.9 0.9 0.9 1</diffuse>
          <specular>0.1 0.1 0.1 1</specular>
        </material>
      </visual>
      <visual name="motor_visual">
        <pose degrees="true">0.05 0 0 0 90 0</pose>
        <geometry>
          <cylinder>
            <radius>0.012</radius>
            <length>0.026</length>
          </cylinder>
        </geometry>
        <material>
          <ambient>0 0 1 1</ambient>
          <diffuse>0 0 1 1</diffuse>
          <specular>0.1 0.1 0.1 1</specular>
        </material>
      </visual>
    </link>
    <joint name="wing_back_right_joint" type="revolute">
      <pose>0.0275 0.075 0 0 0 0</pose>
      <parent>fuselage_back_link</parent>
      <child>wing_back_right_link</child>
      <axis>
        <xyz>0 1 0</xyz>
        <limit>
          <lower>-1.57079632</lower>
          <upper>1.57079632</upper>
        </limit>
        <dynamics>
          <damping>0.01</damping>
        </dynamics>
      </axis>
    </joint>

    <link name="motor_front_left_link">
      <pose degrees="true">0.1225 0.125 0 0 90 0</pose>
      <inertial>
        <mass>0.033</mass>
        <inertia>
          <ixx>3.25325E-06</ixx>
          <ixy>0</ixy>
          <ixz>0</ixz>
          <iyy>3.25325E-06</iyy>
          <iyz>0</iyz>
          <izz>2.7885E-06</izz>
        </inertia>
      </inertial>
      <collision name="collision">
        <geometry>
          <cylinder>
            <radius>0.013</radius>
            <length>0.026</length>
          </cylinder>
        </geometry>
      </collision>
      <visual name="visual">
        <geometry>
          <cylinder>
            <radius>0.013</radius>
            <length>0.026</length>
          </cylinder>
        </geometry>
        <material>
          <ambient>0.1 0.1 0.1 1</ambient>
          <diffuse>0.1 0.1 0.1 1</diffuse>
          <specular>0.1 0.1 0.1 1</specular>
        </material>
      </visual>
      <visual name="prop_blade_1_visual">
        <pose degrees="true">0.030625 0 0.015 0 0 0</pose>
        <geometry>
          <box>
            <size>0.06125 0.01 0.002</size>
          </box>
        </geometry>
        <material>
          <ambient>0 1 0 1</ambient>
          <diffuse>0 1 0 1</diffuse>
          <specular>0.1 0.1 0.1 1</specular>
        </material>
      </visual>
      <visual name="prop_blade_2_visual">
        <pose degrees="true">-0.0153125 0.026522027990898433 0.015 0 0 120</pose>
        <geometry>
          <box>
            <size>0.06125 0.01 0.002</size>
          </box>
        </geometry>
        <material>
          <ambient>0 1 0 1</ambient>
          <diffuse>0 1 0 1</diffuse>
          <specular>0.1 0.1 0.1 1</specular>
        </material>
      </visual>
      <visual name="prop_blade_3_visual">
        <pose degrees="true">-0.0153125 -0.026522027990898433 0.015 0 0 240</pose>
        <geometry>
          <box>
            <size>0.06125 0.01 0.002</size>
          </box>
        </geometry>
        <material>
          <ambient>0 1 0 1</ambient>
          <diffuse>0 1 0 1</diffuse>
          <specular>0.1 0.1 0.1 1</specular>
        </material>
      </visual>
    </link>
    <joint name="motor_front_left_joint" type="revolute">
      <pose>0 0 0 0 0 0</pose>
      <parent>wing_front_left_link</parent>
      <child>motor_front_left_link</child>
      <axis>
        <xyz>0 0 1</xyz>
        <limit>
          <lower>-1.0e16</lower>
          <upper>1.0e16</upper>
        </limit>
        <dynamics>
          <damping>0.004</damping>
        </dynamics>
      </axis>
    </joint>

    <link name="motor_front_right_link">
      <pose degrees="true">0.1225 -0.125 0 0 90 0</pose>
      <inertial>
        <mass>0.033</mass>
        <inertia>
          <ixx>3.25325E-06</ixx>
          <ixy>0</ixy>
          <ixz>0</ixz>
          <iyy>3.25325E-06</iyy>
          <iyz>0</iyz>
          <izz>2.7885E-06</izz>
        </inertia>
      </inertial>
      <collision name="collision">
        <geometry>
          <cylinder>
            <radius>0.013</radius>
            <length>0.026</length>
          </cylinder>
        </geometry>
      </collision>
      <visual name="visual">
        <geometry>
          <cylinder>
            <radius>0.013</radius>
            <length>0.026</length>
          </cylinder>
        </geometry>
        <material>
          <ambient>0.1 0.1 0.1 1</ambient>
          <diffuse>0.1 0.1 0.1 1</diffuse>
          <specular>0.1 0.1 0.1 1</specular>
        </material>
      </visual>
      <visual name="prop_blade_1_visual">
        <pose degrees="true">0.030625 0 0.015 0 0 0</pose>
        <geometry>
          <box>
            <size>0.06125 0.01 0.002</size>
          </box>
        </geometry>
        <material>
          <ambient>0 0 1 1</ambient>
          <diffuse>0 0 1 1</diffuse>
          <specular>0.1 0.1 0.1 1</specular>
        </material>
      </visual>
      <visual name="prop_blade_2_visual">
        <pose degrees="true">-0.0153125 0.026522027990898433 0.015 0 0 120</pose>
        <geometry>
          <box>
            <size>0.06125 0.01 0.002</size>
          </box>
        </geometry>
        <material>
          <ambient>0 0 1 1</ambient>
          <diffuse>0 0 1 1</diffuse>
          <specular>0.1 0.1 0.1 1</specular>
        </material>
      </visual>
      <visual name="prop_blade_3_visual">
        <pose degrees="true">-0.0153125 -0.026522027990898433 0.015 0 0 240</pose>
        <geometry>
          <box>
            <size>0.06125 0.01 0.002</size>
          </box>
        </geometry>
        <material>
          <ambient>0 0 1 1</ambient>
          <diffuse>0 0 1 1</diffuse>
          <specular>0.1 0.1 0.1 1</specular>
        </material>
      </visual>
    </link>
    <joint name="motor_front_right_joint" type="revolute">
      <pose>0 0 0 0 0 0</pose>
      <parent>wing_front_right_link</parent>
      <child>motor_front_right_link</child>
      <axis>
        <xyz>0 0 1</xyz>
        <limit>
          <lower>-1.0e16</lower>
          <upper>1.0e16</upper>
        </limit>
        <dynamics>
          <damping>0.004</damping>
        </dynamics>
      </axis>
    </joint>

    <link name="motor_back_left_link">
      <pose degrees="true">-0.0675 0.125 0 0 90 0</pose>
      <inertial>
        <mass>0.033</mass>
        <inertia>
          <ixx>3.25325E-06</ixx>
          <ixy>0</ixy>
          <ixz>0</ixz>
          <iyy>3.25325E-06</iyy>
          <iyz>0</iyz>
          <izz>2.7885E-06</izz>
        </inertia>
      </inertial>
      <collision name="collision">
        <geometry>
          <cylinder>
            <radius>0.013</radius>
            <length>0.026</length>
          </cylinder>
        </geometry>
      </collision>
      <visual name="visual">
        <geometry>
          <cylinder>
            <radius>0.013</radius>
            <length>0.026</length>
          </cylinder>
        </geometry>
        <material>
          <ambient>0.1 0.1 0.1 1</ambient>
          <diffuse>0.1 0.1 0.1 1</diffuse>
          <specular>0.1 0.1 0.1 1</specular>
        </material>
      </visual>
      <visual name="prop_blade_1_visual">
        <pose degrees="true">0.030625 0 0.015 0 0 0</pose>
        <geometry>
          <box>
            <size>0.06125 0.01 0.002</size>
          </box>
        </geometry>
        <material>
          <ambient>0 0 1 1</ambient>
          <diffuse>0 0 1 1</diffuse>
          <specular>0.1 0.1 0.1 1</specular>
        </material>
      </visual>
      <visual name="prop_blade_2_visual">
        <pose degrees="true">-0.0153125 0.026522027990898433 0.015 0 0 120</pose>
        <geometry>
          <box>
            <size>0.06125 0.01 0.002</size>
          </box>
        </geometry>
        <material>
          <ambient>0 0 1 1</ambient>
          <diffuse>0 0 1 1</diffuse>
          <specular>0.1 0.1 0.1 1</specular>
        </material>
      </visual>
      <visual name="prop_blade_3_visual">
        <pose degrees="true">-0.0153125 -0.026522027990898433 0.015 0 0 240</pose>
        <geometry>
          <box>
            <size>0.06125 0.01 0.002</size>
          </box>
        </geometry>
        <material>
          <ambient>0 0 1 1</ambient>
          <diffuse>0 0 1 1</diffuse>
          <specular>0.1 0.1 0.1 1</specular>
        </material>
      </visual>
    </link>
    <joint name="motor_back_left_joint" type="revolute">
      <pose>0 0 0 0 0 0</pose>
      <parent>wing_back_left_link</parent>
      <child>motor_back_left_link</child>
      <axis>
        <xyz>0 0 1</xyz>
        <limit>
          <lower>-1.0e16</lower>
          <upper>1.0e16</upper>
        </limit>
        <dynamics>
          <damping>0.004</damping>
        </dynamics>
      </axis>
    </joint>

    <link name="motor_back_right_link">
      <pose degrees="true">-0.0675 -0.125 0 0 90 0</pose>
      <inertial>
        <mass>0.033</mass>
        <inertia>
          <ixx>3.25325E-06</ixx>
          <ixy>0</ixy>
          <ixz>0</ixz>
          <iyy>3.25325E-06</iyy>
          <iyz>0</iyz>
          <izz>2.7885E-06</izz>
        </inertia>
      </inertial>
      <collision name="collision">
        <geometry>
          <cylinder>
            <radius>0.013</radius>
            <length>0.026</length>
          </cylinder>
        </geometry>
      </collision>
      <visual name="visual">
        <geometry>
          <cylinder>
            <radius>0.013</radius>
            <length>0.026</length>
          </cylinder>
        </geometry>
        <material>
          <ambient>0.1 0.1 0.1 1</ambient>
          <diffuse>0.1 0.1 0.1 1</diffuse>
          <specular>0.1 0.1 0.1 1</specular>
        </material>
      </visual>
      <visual name="prop_blade_1_visual">
        <pose degrees="true">0.030625 0 0.015 0 0 0</pose>
        <geometry>
          <box>
            <size>0.06125 0.01 0.002</size>
          </box>
        </geometry>
        <material>
          <ambient>0 1 0 1</ambient>
          <diffuse>0 1 0 1</diffuse>
          <specular>0.1 0.1 0.1 1</specular>
        </material>
      </visual>
      <visual name="prop_blade_2_visual">
        <pose degrees="true">-0.0153125 0.026522027990898433 0.015 0 0 120</pose>
        <geometry>
          <box>
            <size>0.06125 0.01 0.002</size>
          </box>
        </geometry>
        <material>
          <ambient>0 1 0 1</ambient>
          <diffuse>0 1 0 1</diffuse>
          <specular>0.1 0.1 0.1 1</specular>
        </material>
      </visual>
      <visual name="prop_blade_3_visual">
        <pose degrees="true">-0.0153125 -0.026522027990898433 0.015 0 0 240</pose>
        <geometry>
          <box>
            <size>0.06125 0.01 0.002</size>
          </box>
        </geometry>
        <material>
          <ambient>0 1 0 1</ambient>
          <diffuse>0 1 0 1</diffuse>
          <specular>0.1 0.1 0.1 1</specular>
        </material>
      </visual>
    </link>
    <joint name="motor_back_right_joint" type="revolute">
      <pose>0 0 0 0 0 0</pose>
      <parent>wing_back_right_link</parent>
      <child>motor_back_right_link</child>
      <axis>
        <xyz>0 0 1</xyz>
        <limit>
          <lower>-1.0e16</lower>
          <upper>1.0e16</upper>
        </limit>
        <dynamics>
          <damping>0.004</damping>
        </dynamics>
      </axis>
    </joint>

    <!-- plugins -->
    <plugin name="gz::sim::systems::JointStatePublisher"
        filename="gz-sim-joint-state-publisher-system">
    </plugin>

    <plugin name="gz::sim::systems::JointPositionController"
        filename="gz-sim-joint-position-controller-system">
      <joint_name>wing_front_left_joint</joint_name>
      <topic>/model/morphing_quad/joint/wing_front_left_joint/cmd_pos</topic>
      <initial_position>-1.57079632</initial_position>
      <p_gain>0.4</p_gain>
      <i_gain>0</i_gain>
      <d_gain>1.0e-2</d_gain>
      <i_max>1</i_max>
      <i_min>-1</i_min>
      <cmd_max>1.0e4</cmd_max>
      <cmd_min>-1.0e4</cmd_min>
    </plugin>
    <plugin name="gz::sim::systems::JointPositionController"
        filename="gz-sim-joint-position-controller-system">
      <joint_name>wing_front_right_joint</joint_name>
      <topic>/model/morphing_quad/joint/wing_front_right_joint/cmd_pos</topic>
      <initial_position>-1.57079632</initial_position>
      <p_gain>0.4</p_gain>
      <i_gain>0</i_gain>
      <d_gain>1.0e-2</d_gain>
      <i_max>1</i_max>
      <i_min>-1</i_min>
      <cmd_max>1.0e4</cmd_max>
      <cmd_min>-1.0e4</cmd_min>
    </plugin>
    <plugin name="gz::sim::systems::JointPositionController"
        filename="gz-sim-joint-position-controller-system">
      <joint_name>wing_back_left_joint</joint_name>
      <topic>/model/morphing_quad/joint/wing_back_left_joint/cmd_pos</topic>
      <initial_position>-1.57079632</initial_position>
      <p_gain>0.4</p_gain>
      <i_gain>0</i_gain>
      <d_gain>1.0e-2</d_gain>
      <i_max>1</i_max>
      <i_min>-1</i_min>
      <cmd_max>1.0e4</cmd_max>
      <cmd_min>-1.0e4</cmd_min>
    </plugin>
    <plugin name="gz::sim::systems::JointPositionController"
        filename="gz-sim-joint-position-controller-system">
      <joint_name>wing_back_right_joint</joint_name>
      <topic>/model/morphing_quad/joint/wing_back_right_joint/cmd_pos</topic>
      <initial_position>-1.57079632</initial_position>
      <p_gain>0.4</p_gain>
      <i_gain>0</i_gain>
      <d_gain>1.0e-2</d_gain>
      <i_max>1</i_max>
      <i_min>-1</i_min>
      <cmd_max>1.0e4</cmd_max>
      <cmd_min>-1.0e4</cmd_min>
    </plugin>

    <plugin name="gz::sim::systems::JointController"
      filename="gz-sim-joint-controller-system">
      <joint_name>motor_front_left_joint</joint_name>
      <use_force_commands>1</use_force_commands>
      <topic>/model/morphing_quad/joint/motor_front_left_joint/cmd_vel</topic>
      <initial_velocity>0.0</initial_velocity>
      <p_gain>0.001</p_gain>
      <d_gain>1.0e-8</d_gain>
      <cmd_max>1.0e3</cmd_max>
      <cmd_min>-1.0e3</cmd_min>
    </plugin>
    <plugin name="gz::sim::systems::JointController"
      filename="gz-sim-joint-controller-system">
      <joint_name>motor_front_right_joint</joint_name>
      <use_force_commands>1</use_force_commands>
      <topic>/model/morphing_quad/joint/motor_front_right_joint/cmd_vel</topic>
      <initial_velocity>0.0</initial_velocity>
      <p_gain>0.001</p_gain>
      <d_gain>1.0e-8</d_gain>
      <cmd_max>1.0e3</cmd_max>
      <cmd_min>-1.0e3</cmd_min>
    </plugin>
    <plugin name="gz::sim::systems::JointController"
      filename="gz-sim-joint-controller-system">
      <joint_name>motor_back_left_joint</joint_name>
      <use_force_commands>1</use_force_commands>
      <topic>/model/morphing_quad/joint/motor_back_left_joint/cmd_vel</topic>
      <initial_velocity>0.0</initial_velocity>
      <p_gain>0.001</p_gain>
      <d_gain>1.0e-8</d_gain>
      <cmd_max>1.0e3</cmd_max>
      <cmd_min>-1.0e3</cmd_min>
    </plugin>
    <plugin name="gz::sim::systems::JointController"
      filename="gz-sim-joint-controller-system">
      <joint_name>motor_back_right_joint</joint_name>
      <use_force_commands>1</use_force_commands>
      <topic>/model/morphing_quad/joint/motor_back_right_joint/cmd_vel</topic>
      <initial_velocity>0.0</initial_velocity>
      <p_gain>0.001</p_gain>
      <d_gain>1.0e-8</d_gain>
      <cmd_max>1.0e3</cmd_max>
      <cmd_min>-1.0e3</cmd_min>
    </plugin>

    <!-- Motor1 CCW motor_front_right_link -->
    <plugin name="gz::sim::systems::LiftDrag"
      filename="gz-sim-lift-drag-system">
      <a0>0.3</a0>
      <alpha_stall>1.4</alpha_stall>
      <cla>4.2500</cla>
      <cda>0.10</cda>
      <cma>0.00</cma>
      <cla_stall>-0.025</cla_stall>
      <cda_stall>0.0</cda_stall>
      <cma_stall>0.0</cma_stall>
      <area>0.0015</area>
      <air_density>1.2041</air_density>
      <cp>0.063 0 0</cp>
      <forward>0 1 0</forward>
      <upward>0 0 1</upward>
      <link_name>motor_front_right_link</link_name>
    </plugin>
    <plugin name="gz::sim::systems::LiftDrag"
      filename="gz-sim-lift-drag-system">
      <a0>0.3</a0>
      <alpha_stall>1.4</alpha_stall>
      <cla>4.2500</cla>
      <cda>0.10</cda>
      <cma>0.00</cma>
      <cla_stall>-0.025</cla_stall>
      <cda_stall>0.0</cda_stall>
      <cma_stall>0.0</cma_stall>
      <area>0.0015</area>
      <air_density>1.2041</air_density>
      <cp>-0.0315 0.0545596 0</cp>
      <forward>-0.866025404 -0.5 0</forward>
      <upward>0 0 1</upward>
      <link_name>motor_front_right_link</link_name>
    </plugin>
    <plugin name="gz::sim::systems::LiftDrag"
      filename="gz-sim-lift-drag-system">
      <a0>0.3</a0>
      <alpha_stall>1.4</alpha_stall>
      <cla>4.2500</cla>
      <cda>0.10</cda>
      <cma>0.00</cma>
      <cla_stall>-0.025</cla_stall>
      <cda_stall>0.0</cda_stall>
      <cma_stall>0.0</cma_stall>
      <area>0.0015</area>
      <air_density>1.2041</air_density>
      <cp>-0.0315 -0.0545596 0</cp>
      <forward>0.866025404 -0.5 0</forward>
      <upward>0 0 1</upward>
      <link_name>motor_front_right_link</link_name>
    </plugin>

    <!-- Motor2 CCW motor_back_left_link -->
    <plugin name="gz::sim::systems::LiftDrag"
      filename="gz-sim-lift-drag-system">
      <a0>0.3</a0>
      <alpha_stall>1.4</alpha_stall>
      <cla>4.2500</cla>
      <cda>0.10</cda>
      <cma>0.00</cma>
      <cla_stall>-0.025</cla_stall>
      <cda_stall>0.0</cda_stall>
      <cma_stall>0.0</cma_stall>
      <area>0.0015</area>
      <air_density>1.2041</air_density>
      <cp>0.063 0 0</cp>
      <forward>0 1 0</forward>
      <upward>0 0 1</upward>
      <link_name>motor_back_left_link</link_name>
    </plugin>
    <plugin name="gz::sim::systems::LiftDrag"
      filename="gz-sim-lift-drag-system">
      <a0>0.3</a0>
      <alpha_stall>1.4</alpha_stall>
      <cla>4.2500</cla>
      <cda>0.10</cda>
      <cma>0.00</cma>
      <cla_stall>-0.025</cla_stall>
      <cda_stall>0.0</cda_stall>
      <cma_stall>0.0</cma_stall>
      <area>0.0015</area>
      <air_density>1.2041</air_density>
      <cp>-0.0315 0.0545596 0</cp>
      <forward>-0.866025404 -0.5 0</forward>
      <upward>0 0 1</upward>
      <link_name>motor_back_left_link</link_name>
    </plugin>
    <plugin name="gz::sim::systems::LiftDrag"
      filename="gz-sim-lift-drag-system">
      <a0>0.3</a0>
      <alpha_stall>1.4</alpha_stall>
      <cla>4.2500</cla>
      <cda>0.10</cda>
      <cma>0.00</cma>
      <cla_stall>-0.025</cla_stall>
      <cda_stall>0.0</cda_stall>
      <cma_stall>0.0</cma_stall>
      <area>0.0015</area>
      <air_density>1.2041</air_density>
      <cp>-0.0315 -0.0545596 0</cp>
      <forward>0.866025404 -0.5 0</forward>
      <upward>0 0 1</upward>
      <link_name>motor_back_left_link</link_name>
    </plugin>

    <!-- Motor3 CW motor_front_left_link -->
    <plugin name="gz::sim::systems::LiftDrag"
      filename="gz-sim-lift-drag-system">
      <a0>0.3</a0>
      <alpha_stall>1.4</alpha_stall>
      <cla>4.2500</cla>
      <cda>0.10</cda>
      <cma>0.00</cma>
      <cla_stall>-0.025</cla_stall>
      <cda_stall>0.0</cda_stall>
      <cma_stall>0.0</cma_stall>
      <area>0.0015</area>
      <air_density>1.2041</air_density>
      <cp>0.063 0 0</cp>
      <forward>0 -1 0</forward>
      <upward>0 0 1</upward>
      <link_name>motor_front_left_link</link_name>
    </plugin>
    <plugin name="gz::sim::systems::LiftDrag"
      filename="gz-sim-lift-drag-system">
      <a0>0.3</a0>
      <alpha_stall>1.4</alpha_stall>
      <cla>4.2500</cla>
      <cda>0.10</cda>
      <cma>0.00</cma>
      <cla_stall>-0.025</cla_stall>
      <cda_stall>0.0</cda_stall>
      <cma_stall>0.0</cma_stall>
      <area>0.0015</area>
      <air_density>1.2041</air_density>
      <cp>-0.0315 0.0545596 0</cp>
      <forward>0.866025404 0.5 0</forward>
      <upward>0 0 1</upward>
      <link_name>motor_front_left_link</link_name>
    </plugin>
    <plugin name="gz::sim::systems::LiftDrag"
      filename="gz-sim-lift-drag-system">
      <a0>0.3</a0>
      <alpha_stall>1.4</alpha_stall>
      <cla>4.2500</cla>
      <cda>0.10</cda>
      <cma>0.00</cma>
      <cla_stall>-0.025</cla_stall>
      <cda_stall>0.0</cda_stall>
      <cma_stall>0.0</cma_stall>
      <area>0.0015</area>
      <air_density>1.2041</air_density>
      <cp>-0.0315 -0.0545596 0</cp>
      <forward>-0.866025404 0.5 0</forward>
      <upward>0 0 1</upward>
      <link_name>motor_front_left_link</link_name>
    </plugin>

    <!-- Motor4 CW motor_back_right_link -->
    <plugin name="gz::sim::systems::LiftDrag"
      filename="gz-sim-lift-drag-system">
      <a0>0.3</a0>
      <alpha_stall>1.4</alpha_stall>
      <cla>4.2500</cla>
      <cda>0.10</cda>
      <cma>0.00</cma>
      <cla_stall>-0.025</cla_stall>
      <cda_stall>0.0</cda_stall>
      <cma_stall>0.0</cma_stall>
      <area>0.0015</area>
      <air_density>1.2041</air_density>
      <cp>0.063 0 0</cp>
      <forward>0 -1 0</forward>
      <upward>0 0 1</upward>
      <link_name>motor_back_right_link</link_name>
    </plugin>
    <plugin name="gz::sim::systems::LiftDrag"
      filename="gz-sim-lift-drag-system">
      <a0>0.3</a0>
      <alpha_stall>1.4</alpha_stall>
      <cla>4.2500</cla>
      <cda>0.10</cda>
      <cma>0.00</cma>
      <cla_stall>-0.025</cla_stall>
      <cda_stall>0.0</cda_stall>
      <cma_stall>0.0</cma_stall>
      <area>0.0015</area>
      <air_density>1.2041</air_density>
      <cp>-0.0315 0.0545596 0</cp>
      <forward>0.866025404 0.5 0</forward>
      <upward>0 0 1</upward>
      <link_name>motor_back_right_link</link_name>
    </plugin>
    <plugin name="gz::sim::systems::LiftDrag"
      filename="gz-sim-lift-drag-system">
      <a0>0.3</a0>
      <alpha_stall>1.4</alpha_stall>
      <cla>4.2500</cla>
      <cda>0.10</cda>
      <cma>0.00</cma>
      <cla_stall>-0.025</cla_stall>
      <cda_stall>0.0</cda_stall>
      <cma_stall>0.0</cma_stall>
      <area>0.0015</area>
      <air_density>1.2041</air_density>
      <cp>-0.0315 -0.0545596 0</cp>
      <forward>-0.866025404 0.5 0</forward>
      <upward>0 0 1</upward>
      <link_name>motor_back_right_link</link_name>
    </plugin>

    <plugin name="ArduPilotPlugin" filename="ArduPilotPlugin">
      <!-- Port settings -->
      <fdm_addr>127.0.0.1</fdm_addr>
      <fdm_port_in>9002</fdm_port_in>
      <connectionTimeoutMaxCount>5</connectionTimeoutMaxCount>
      <lock_step>1</lock_step>
      <have_32_channels>0</have_32_channels>

      <!-- Frame conventions -->
      <modelXYZToAirplaneXForwardZDown degrees="true">0 0 0 180 0 0</modelXYZToAirplaneXForwardZDown>
      <gazeboXYZToNED degrees="true">0 0 0 180 0 90</gazeboXYZToNED>

      <!-- Sensors -->
      <imuName>base_link::imu_sensor</imuName>

      <!-- motor1: ccw -->
      <control channel="0">
        <jointName>motor_front_right_joint</jointName>
        <multiplier>800</multiplier>
        <offset>0</offset>
        <servo_min>1000</servo_min>
        <servo_max>2000</servo_max>
        <type>COMMAND</type>
        <cmd_topic>/model/morphing_quad/joint/motor_front_right_joint/cmd_vel</cmd_topic>
      </control>

      <!-- motor2: ccw -->
      <control channel="1">
        <jointName>motor_back_left_joint</jointName>
        <multiplier>800</multiplier>
        <offset>0</offset>
        <servo_min>1000</servo_min>
        <servo_max>2000</servo_max>
        <type>COMMAND</type>
        <cmd_topic>/model/morphing_quad/joint/motor_back_left_joint/cmd_vel</cmd_topic>
        </control>

      <!-- motor3: cw -->
      <control channel="2">
          <jointName>motor_front_left_joint</jointName>
          <multiplier>-800</multiplier>
          <offset>0</offset>
          <servo_min>1000</servo_min>
          <servo_max>2000</servo_max>
          <type>COMMAND</type>
          <cmd_topic>/model/morphing_quad/joint/motor_front_left_joint/cmd_vel</cmd_topic>
        </control>
  
      <!-- motor4: cw -->
      <control channel="3">
          <jointName>motor_back_right_joint</jointName>
          <multiplier>-800</multiplier>
          <offset>0</offset>
          <servo_min>1000</servo_min>
          <servo_max>2000</servo_max>
          <type>COMMAND</type>
          <cmd_topic>/model/morphing_quad/joint/motor_back_right_joint/cmd_vel</cmd_topic>
        </control>

      <!-- front wing tilt -->
      <control channel="5">
        <jointName>wing_front_left_joint</jointName>
        <multiplier>-1.57079632</multiplier>
        <offset>0</offset>
        <servo_min>1000</servo_min>
        <servo_max>2000</servo_max>
        <type>COMMAND</type>
        <cmd_topic>/model/morphing_quad/joint/wing_front_left_joint/cmd_pos</cmd_topic>
      </control>
      <control channel="5">
        <jointName>wing_front_right_joint</jointName>
        <multiplier>-1.57079632</multiplier>
        <offset>0</offset>
        <servo_min>1000</servo_min>
        <servo_max>2000</servo_max>
        <type>COMMAND</type>
        <cmd_topic>/model/morphing_quad/joint/wing_front_right_joint/cmd_pos</cmd_topic>
      </control>

      <!-- rear wing tilt -->
      <control channel="6">
        <jointName>wing_back_left_joint</jointName>
        <multiplier>-1.57079632</multiplier>
        <offset>0</offset>
        <servo_min>1000</servo_min>
        <servo_max>2000</servo_max>
        <type>COMMAND</type>
        <cmd_topic>/model/morphing_quad/joint/wing_back_left_joint/cmd_pos</cmd_topic>
      </control>
      <control channel="6">
        <jointName>wing_back_right_joint</jointName>
        <multiplier>-1.57079632</multiplier>
        <offset>0</offset>
        <servo_min>1000</servo_min>
        <servo_max>2000</servo_max>
        <type>COMMAND</type>
        <cmd_topic>/model/morphing_quad/joint/wing_back_right_joint/cmd_pos</cmd_topic>
      </control>
    </plugin>
  </model>
</sdf>
