<?xml version="1.0"?>
<!--
  Dimensions
  ==========

  Prop  : 5 inch
  Motor : model:  tbd
          mass:   tbd
          size:   tbd
          thrust: tbd
  ESC   : tbd
  Servo : model:  tbd
          mass:   tbd
          torque: tbd
          size:   tbd

  Wing:   span:   0.150m
          chord:  0.110m


  Wing joint position controllers
  ===============================

  gz topic -t /model/morphing_quad/joint/wing_front_left_joint/cmd_pos -m gz.msgs.Double -p "data: -1.57"

  Motor joint velocity controllers
  ================================

  gz topic -t /model/morphing_quad/joint/motor_front_left_joint/cmd_vel -m gz.msgs.Double -p "data: -1.57"

  ArduPilot copter params
  =======================

  The vehicle is run as an X-frame quadcopter. The attitude gains are
  calculated using the VTOL-quicktune.lua script which is enabled with RC9.
  
  For testing the wing tilt servo outputs use the outputs of RC6 and RC7. 

  Parameter        Current  Default
  FRAME_TYPE       1.000000 0.000000 # X (DEFAULT: Plus)
  ATC_ACCEL_Y_MAX  30000.000000 27000.000000
  ATC_ACCEL_R_MAX  160000.000000 110000.000000
  ATC_ACCEL_P_MAX  160000.000000 110000.000000
  ATC_RAT_RLL_P    0.108000 0.135000
  ATC_RAT_RLL_I    0.108000 0.135000
  ATC_RAT_RLL_D    0.002880 0.003600
  ATC_RAT_RLL_FLTT 40.000000 20.000000
  ATC_RAT_RLL_FLTD 40.000000 20.000000
  ATC_RAT_RLL_SMAX 50.000000 0.000000
  ATC_RAT_PIT_P    0.108000 0.135000
  ATC_RAT_PIT_I    0.108000 0.135000
  ATC_RAT_PIT_D    0.002880 0.003600
  ATC_RAT_PIT_FLTT 40.000000 20.000000
  ATC_RAT_PIT_FLTD 40.000000 20.000000
  ATC_RAT_PIT_SMAX 50.000000 0.000000
  ATC_RAT_YAW_P    0.500000 0.300000
  ATC_RAT_YAW_I    0.050000 0.020000
  ATC_RAT_YAW_D    0.010000 0.000000
  ATC_RAT_YAW_FLTT 40.000000 20.000000
  ATC_RAT_YAW_FLTD 40.000000 20.000000
  ATC_RAT_YAW_SMAX 50.000000 0.000000
  MOT_THST_EXPO    0.550000 0.650000
  MOT_THST_HOVER   0.125275 0.390000
  SERVO1_MIN       1000.000000 1100.000000
  SERVO1_MAX       2000.000000 1900.000000
  SERVO2_MIN       1000.000000 1100.000000
  SERVO2_MAX       2000.000000 1900.000000
  SERVO3_MIN       1000.000000 1100.000000
  SERVO3_MAX       2000.000000 1900.000000
  SERVO4_MIN       1000.000000 1100.000000
  SERVO4_MAX       2000.000000 1900.000000
  SERVO6_MIN       1000.000000 1100.000000
  SERVO6_MAX       2000.000000 1900.000000
  SERVO6_FUNCTION  56.000000 0.000000 # RCIN6 (DEFAULT: Disabled)
  SERVO7_MIN       1000.000000 1100.000000
  SERVO7_MAX       2000.000000 1900.000000
  SERVO7_FUNCTION  57.000000 0.000000 # RCIN7 (DEFAULT: Disabled)
  RC6_TRIM         1000.000000 1500.000000
  RC7_OPTION       0.000000 7.000000 # Do Nothing (DEFAULT: Save WP)
  RC8_OPTION       0.000000 39.000000 # Do Nothing (DEFAULT: PrecLoiter Enable)
  RC9_OPTION       300.000000 0.000000 # Scripting1 (DEFAULT: Do Nothing)
  SCR_ENABLE       1.000000 0.000000 # Lua Scripts (DEFAULT: None)
  QUIK_ENABLE      1.0         # Enabled

  ArduPilot quadplane params
  ==========================

  sim_vehicle.py -/-debug -v ArduPlane -f quadplane -/-model json -/-console

  Python to calculate control offset and multiplier for joint pos controllers

  def calc_multiplier_and_offset(lower, upper):
       offset = (lower/upper)/(1.0 - lower/upper)
       mult = upper/(1 + offset)
       return mult, offset

  Parameter        Current  Default
  AIRSPEED_CRUISE  12.000000 25.000000
  AIRSPEED_MIN     8.000000 13.000000
  AIRSPEED_MAX     20.000000 35.000000
  THR_FAILSAFE     0.000000 1.000000 # Disabled (DEFAULT: Enabled)
  FLTMODE1         0.000000 10.000000 # Manual (DEFAULT: Auto)
  FLTMODE2         17.000000 11.000000 # QSTABILIZE (DEFAULT: RTL)
  FLTMODE3         18.000000 12.000000 # QHOVER (DEFAULT: Loiter)
  FLTMODE4         17.000000 5.000000 # QSTABILIZE (DEFAULT: FBWA)
  FLTMODE5         5.000000 19.000000 # FBWA (DEFAULT: QLOITER)
  FLTMODE6         10.000000 5.000000 # Auto (DEFAULT: FBWA)
  SCALING_SPEED    12.000000 15.000000
  ARMING_RUDDER    0.000000 2.000000 # Disabled (DEFAULT: ArmOrDisarm)
  Q_M_THST_EXPO    0.550000 0.650000
  Q_M_THST_HOVER   0.127606 0.350000
  Q_ASSIST_SPEED   10.000000 18.000000
  Q_OPTIONS        1024.000000 0.000000 #  Disarmed Yaw Tilt-enable motor tilt for yaw when disarmed (DEFAULT: )
  Q_TRIM_PITCH     5.000000 0.000000
  Q_TILT_ENABLE    1.000000 0.000000 # Enable (DEFAULT: Disable)
  Q_TILT_MASK      15.000000 0.000000 # Motor 1|Motor 2|Motor 3|Motor 4 (DEFAULT: )
  Q_TILT_TYPE      2.000000 0.000000 # VectoredYaw (DEFAULT: Continuous)
  Q_TILT_YAW_ANGLE 30.000000 0.000000
  Q_TILT_FIX_ANGLE 30.000000 0.000000
  Q_TILT_FIX_GAIN  0.200000 0.000000
  Q_A_ACCEL_Y_MAX  30000.000000 10000.000000
  Q_A_ACCEL_R_MAX  160000.000000 40000.000000
  Q_A_ACCEL_P_MAX  160000.000000 40000.000000
  Q_A_RAT_RLL_P    0.108000 0.150000
  Q_A_RAT_RLL_I    0.108000 0.250000
  Q_A_RAT_RLL_FLTT 40.000000 20.000000
  Q_A_RAT_RLL_FLTD 40.000000 10.000000
  Q_A_RAT_PIT_P    0.108000 0.150000
  Q_A_RAT_PIT_I    0.108000 0.250000
  Q_A_RAT_PIT_FLTT 40.000000 20.000000
  Q_A_RAT_PIT_FLTD 40.000000 10.000000
  Q_A_RAT_YAW_P    0.500000 0.180000
  Q_A_RAT_YAW_I    0.050000 0.018000
  Q_A_RAT_YAW_D    0.010000 0.000000
  Q_A_RAT_YAW_FLTT 40.000000 20.000000
  Q_A_RAT_YAW_FLTD 40.000000 20.000000
  SERVO1_MIN       1000.000000 1100.000000
  SERVO1_MAX       2000.000000 1900.000000
  SERVO2_MIN       1000.000000 1100.000000
  SERVO2_MAX       2000.000000 1900.000000
  SERVO4_MIN       1000.000000 1100.000000
  SERVO4_MAX       2000.000000 1900.000000
  SERVO5_MIN       1000.000000 1100.000000
  SERVO5_MAX       2000.000000 1900.000000
  SERVO6_MIN       1000.000000 1100.000000
  SERVO6_MAX       2000.000000 1900.000000
  SERVO7_MIN       1000.000000 1100.000000
  SERVO7_MAX       2000.000000 1900.000000
  SERVO8_MIN       1000.000000 1100.000000
  SERVO8_MAX       2000.000000 1900.000000
  SERVO9_MIN       1000.000000 1100.000000
  SERVO9_MAX       2000.000000 1900.000000
  SERVO9_REVERSED  1.000000 0.000000 # Reversed (DEFAULT: Normal)
  SERVO9_FUNCTION  75.000000 0.000000 # TiltMotorFrontLeft (DEFAULT: Disabled)
  SERVO10_MIN      1000.000000 1100.000000
  SERVO10_MAX      2000.000000 1900.000000
  SERVO10_REVERSED 1.000000 0.000000 # Reversed (DEFAULT: Normal)
  SERVO10_FUNCTION 76.000000 0.000000 # TiltMotorFrontRight (DEFAULT: Disabled)
  SERVO11_MIN      1000.000000 1100.000000
  SERVO11_MAX      2000.000000 1900.000000
  SERVO11_REVERSED 1.000000 0.000000 # Reversed (DEFAULT: Normal)
  SERVO11_FUNCTION 46.000000 0.000000 # TiltMotorRearLeft (DEFAULT: Disabled)
  SERVO12_MIN      1000.000000 1100.000000
  SERVO12_MAX      2000.000000 1900.000000
  SERVO12_REVERSED 1.000000 0.000000 # Reversed (DEFAULT: Normal)
  SERVO12_FUNCTION 47.000000 0.000000 # TiltMotorRearRight (DEFAULT: Disabled)
  RC1_MIN          1000.000000 1087.000000
  RC1_MAX          2000.000000 1886.000000
  RC2_MIN          1000.000000 1100.000000
  RC2_MAX          2000.000000 1900.000000
  RC4_MIN          1000.000000 1100.000000
  RC4_MAX          2000.000000 1900.000000
  RC5_MIN          1000.000000 1100.000000
  RC5_TRIM         1000.000000 1500.000000
  RC5_MAX          2000.000000 1900.000000
  RC6_MIN          1000.000000 1100.000000
  RC6_MAX          2000.000000 1900.000000
  RC7_MIN          1000.000000 1100.000000
  RC7_MAX          2000.000000 1900.000000
  RC8_MIN          1000.000000 1100.000000
  RC8_MAX          2000.000000 1900.000000
  RC9_MIN          1000.000000 1100.000000
  RC9_MAX          2000.000000 1900.000000
  RC10_MIN         1000.000000 1100.000000
  RC10_MAX         2000.000000 1900.000000
  ARSPD_TYPE       0.000000 2.000000 # None (DEFAULT: Analog)
  SCR_ENABLE       1.000000 0.000000 # Lua Scripts (DEFAULT: None)

  -->
<sdf version="1.9"> 
  <model name="morphing_quad">
    <pose>0 0 0 0 0 0</pose>
    <link name="base_link">
      <inertial>
        <pose degrees="true">0 0 0 0 90 0</pose>
        <mass>0.3</mass>
        <inertia>
          <ixx>0.0006775</ixx>
          <ixy>0</ixy>
          <ixz>0</ixz>
          <iyy>0.0006775</iyy>
          <iyz>0</iyz>
          <izz>0.000375</izz>
        </inertia>
      </inertial>
      <collision name="collision">
        <pose degrees="true">0 0 0 0 90 0</pose>
        <geometry>
          <!-- <cylinder>
            <radius>0.05</radius>
            <length>0.140</length>
          </cylinder> -->
          <box>
            <size>0.1 0.1 0.140</size>
          </box>
        </geometry>
        <surface>
          <friction>
            <ode>
              <mu>1.0</mu>
              <mu2>1.0</mu2>
            </ode>
          </friction>
        </surface>
      </collision>
      <visual name="visual">
        <pose degrees="true">0 0 0 0 90 0</pose>
        <geometry>
          <cylinder>
            <radius>0.05</radius>
            <length>0.140</length>
          </cylinder>
        </geometry>
        <material>
          <ambient>0.9 0.9 0.9 1</ambient>
          <diffuse>0.9 0.9 0.9 1</diffuse>
          <specular>0.1 0.1 0.1 1</specular>
        </material>
      </visual>
      <sensor name="imu_sensor" type="imu">
        <pose degrees="true">0 0 0 180 0 0</pose>
        <always_on>1</always_on>
        <update_rate>1000.0</update_rate>
      </sensor>
    </link>

    <link name="fuselage_front_link">
      <pose>0.095 0 0 0 0 0</pose>
      <inertial>
        <pose degrees="true">0 0 0 0 90 0</pose>
        <mass>0.05</mass>
        <inertia>
          <ixx>5.54167E-05</ixx>
          <ixy>0</ixy>
          <ixz>0</ixz>
          <iyy>5.54167E-05</iyy>
          <iyz>0</iyz>
          <izz>0.00009</izz>
        </inertia>
      </inertial>
      <collision name="collision">
        <pose degrees="true">0 0 0 0 90 0</pose>
        <geometry>
          <cylinder>
            <radius>0.05</radius>
            <length>0.05</length>
          </cylinder>
        </geometry>
      </collision>
      <collision name="nose_cone_collision">
        <pose degrees="true">0.075 0 0 0 90 0</pose>
        <geometry>
          <cone>
            <radius>0.05</radius>
            <length>0.10</length>
          </cone>
        </geometry>
      </collision>
      <visual name="visual">
        <pose degrees="true">0 0 0 0 90 0</pose>
        <geometry>
          <cylinder>
            <radius>0.05</radius>
            <length>0.05</length>
          </cylinder>
        </geometry>
        <material>
          <ambient>0.5 0.5 0.5 1</ambient>
          <diffuse>0.5 0.5 0.5 1</diffuse>
          <specular>0.1 0.1 0.1 1</specular>
        </material>
      </visual>
      <visual name="nose_cone_visual">
        <pose degrees="true">0.075 0 0 0 90 0</pose>
        <geometry>
          <cone>
            <radius>0.05</radius>
            <length>0.10</length>
          </cone>
        </geometry>
        <material>
          <ambient>1 0 0 1</ambient>
          <diffuse>1 0 0 1</diffuse>
          <specular>0.1 0.1 0.1 1</specular>
        </material>
      </visual>
    </link>
    <joint name="fuselage_front_joint" type="revolute">
      <pose>-0.025 0 0 0 0 0</pose>
      <parent>base_link</parent>
      <child>fuselage_front_link</child>
      <axis>
        <xyz>0 0 1</xyz>
        <limit>
          <lower>0</lower>
          <upper>0</upper>
        </limit>
        <dynamics>
          <damping>0.1</damping>
        </dynamics>
      </axis>
    </joint>

    <link name="fuselage_back_link">
      <pose>-0.095 0 0 0 0 0</pose>
      <inertial>
        <pose degrees="true">0 0 0 0 90 0</pose>
        <mass>0.05</mass>
        <inertia>
          <ixx>5.54167E-05</ixx>
          <ixy>0</ixy>
          <ixz>0</ixz>
          <iyy>5.54167E-05</iyy>
          <iyz>0</iyz>
          <izz>0.00009</izz>
        </inertia>
      </inertial>
      <collision name="collision">
        <pose degrees="true">0 0 0 0 90 0</pose>
        <geometry>
          <cylinder>
            <radius>0.05</radius>
            <length>0.05</length>
          </cylinder>
        </geometry>
      </collision>
      <visual name="visual">
        <pose degrees="true">0 0 0 0 90 0</pose>
        <geometry>
          <cylinder>
            <radius>0.05</radius>
            <length>0.05</length>
          </cylinder>
        </geometry>
        <material>
          <ambient>0.5 0.5 0.5 1</ambient>
          <diffuse>0.5 0.5 0.5 1</diffuse>
          <specular>0.1 0.1 0.1 1</specular>
        </material>
      </visual>
    </link>
    <joint name="fuselage_back_joint" type="revolute">
      <pose>0.025 0 0 0 0 0</pose>
      <parent>base_link</parent>
      <child>fuselage_back_link</child>
      <axis>
        <xyz>0 0 1</xyz>
        <limit>
          <lower>0</lower>
          <upper>0</upper>
        </limit>
        <dynamics>
          <damping>0.1</damping>
        </dynamics>
      </axis>
    </joint>

    <link name="wing_front_left_link">
      <pose>0.0675 0.125 0 0 0 0</pose>
      <inertial>
        <mass>0.025</mass>
        <inertia>
          <ixx>4.70833E-05</ixx>
          <ixy>0</ixy>
          <ixz>0</ixz>
          <iyy>2.54167E-05</iyy>
          <iyz>0</iyz>
          <izz>7.20833E-05</izz>
        </inertia>
      </inertial>
      <collision name="collision">
        <geometry>
          <box>
            <size>0.110 0.150 0.010</size>
          </box>
        </geometry>
      </collision>
      <visual name="visual">
        <geometry>
          <box>
            <size>0.110 0.150 0.010</size>
          </box>
        </geometry>
        <material>
          <ambient>0.9 0.9 0.9 1</ambient>
          <diffuse>0.9 0.9 0.9 1</diffuse>
          <specular>0.1 0.1 0.1 1</specular>
        </material>
      </visual>
      <visual name="motor_visual">
        <pose degrees="true">0.05 0 0 0 90 0</pose>
        <geometry>
          <cylinder>
            <radius>0.012</radius>
            <length>0.026</length>
          </cylinder>
        </geometry>
        <material>
          <ambient>0 0 1 1</ambient>
          <diffuse>0 0 1 1</diffuse>
          <specular>0.1 0.1 0.1 1</specular>
        </material>
      </visual>
      <!-- debug visual for lift-drag centre of pressure -->
      <visual name="cp_visual">
        <pose>0.0275 0 0 0 0 0</pose>
        <geometry>
          <sphere>
            <radius>0.01</radius>
          </sphere>
        </geometry>
        <material>
          <ambient>1 0 0 1</ambient>
          <diffuse>1 0 0 1</diffuse>
          <specular>0.1 0.1 0.1 1</specular>
        </material>
      </visual>
    </link>
    <joint name="wing_front_left_joint" type="revolute">
      <pose>0.0275 -0.075 0 0 0 0</pose>
      <parent>fuselage_front_link</parent>
      <child>wing_front_left_link</child>
      <axis>
        <xyz>0 1 0</xyz>
        <limit>
          <lower>-2.0943951023931953</lower>
          <upper>0.5235987755982988</upper>
        </limit>
        <dynamics>
          <damping>0.01</damping>
        </dynamics>
      </axis>
    </joint>

    <link name="wing_front_right_link">
      <pose>0.0675 -0.125 0 0 0 0</pose>
      <inertial>
        <mass>0.025</mass>
        <inertia>
          <ixx>4.70833E-05</ixx>
          <ixy>0</ixy>
          <ixz>0</ixz>
          <iyy>2.54167E-05</iyy>
          <iyz>0</iyz>
          <izz>7.20833E-05</izz>
        </inertia>
      </inertial>
      <collision name="collision">
        <geometry>
          <box>
            <size>0.110 0.150 0.010</size>
          </box>
        </geometry>
      </collision>
      <visual name="visual">
        <geometry>
          <box>
            <size>0.110 0.150 0.010</size>
          </box>
        </geometry>
        <material>
          <ambient>0.9 0.9 0.9 1</ambient>
          <diffuse>0.9 0.9 0.9 1</diffuse>
          <specular>0.1 0.1 0.1 1</specular>
        </material>
      </visual>
      <visual name="motor_visual">
        <pose degrees="true">0.05 0 0 0 90 0</pose>
        <geometry>
          <cylinder>
            <radius>0.012</radius>
            <length>0.026</length>
          </cylinder>
        </geometry>
        <material>
          <ambient>0 0 1 1</ambient>
          <diffuse>0 0 1 1</diffuse>
          <specular>0.1 0.1 0.1 1</specular>
        </material>
      </visual>
      <!-- debug visual for lift-drag centre of pressure -->
      <visual name="cp_visual">
        <pose>0.0275 0 0 0 0 0</pose>
        <geometry>
          <sphere>
            <radius>0.01</radius>
          </sphere>
        </geometry>
        <material>
          <ambient>1 0 0 1</ambient>
          <diffuse>1 0 0 1</diffuse>
          <specular>0.1 0.1 0.1 1</specular>
        </material>
      </visual>
    </link>
    <joint name="wing_front_right_joint" type="revolute">
      <pose>0.0275 0.075 0 0 0 0</pose>
      <parent>fuselage_front_link</parent>
      <child>wing_front_right_link</child>
      <axis>
        <xyz>0 1 0</xyz>
        <limit>
          <lower>-2.0943951023931953</lower>
          <upper>0.5235987755982988</upper>
        </limit>
        <dynamics>
          <damping>0.01</damping>
        </dynamics>
      </axis>
    </joint>

    <link name="wing_back_left_link">
      <pose>-0.1225 0.125 0 0 0 0</pose>
      <inertial>
        <mass>0.025</mass>
        <inertia>
          <ixx>4.70833E-05</ixx>
          <ixy>0</ixy>
          <ixz>0</ixz>
          <iyy>2.54167E-05</iyy>
          <iyz>0</iyz>
          <izz>7.20833E-05</izz>
        </inertia>
      </inertial>
      <collision name="collision">
        <geometry>
          <box>
            <size>0.110 0.150 0.010</size>
          </box>
        </geometry>
      </collision>
      <visual name="visual">
        <geometry>
          <box>
            <size>0.110 0.150 0.010</size>
          </box>
        </geometry>
        <material>
          <ambient>0.9 0.9 0.9 1</ambient>
          <diffuse>0.9 0.9 0.9 1</diffuse>
          <specular>0.1 0.1 0.1 1</specular>
        </material>
      </visual>
      <visual name="motor_visual">
        <pose degrees="true">0.05 0 0 0 90 0</pose>
        <geometry>
          <cylinder>
            <radius>0.012</radius>
            <length>0.026</length>
          </cylinder>
        </geometry>
        <material>
          <ambient>0 0 1 1</ambient>
          <diffuse>0 0 1 1</diffuse>
          <specular>0.1 0.1 0.1 1</specular>
        </material>
      </visual>
      <!-- debug visual for lift-drag centre of pressure -->
      <visual name="cp_visual">
        <pose>0.0275 0 0 0 0 0</pose>
        <geometry>
          <sphere>
            <radius>0.01</radius>
          </sphere>
        </geometry>
        <material>
          <ambient>1 0 0 1</ambient>
          <diffuse>1 0 0 1</diffuse>
          <specular>0.1 0.1 0.1 1</specular>
        </material>
      </visual>
    </link>
    <joint name="wing_back_left_joint" type="revolute">
      <pose>0.0275 -0.075 0 0 0 0</pose>
      <parent>fuselage_back_link</parent>
      <child>wing_back_left_link</child>
      <axis>
        <xyz>0 1 0</xyz>
        <limit>
          <lower>-2.0943951023931953</lower>
          <upper>0.5235987755982988</upper>
        </limit>
        <dynamics>
          <damping>0.01</damping>
        </dynamics>
      </axis>
    </joint>

    <link name="wing_back_right_link">
      <pose>-0.1225 -0.125 0 0 0 0</pose>
      <inertial>
        <mass>0.025</mass>
        <inertia>
          <ixx>4.70833E-05</ixx>
          <ixy>0</ixy>
          <ixz>0</ixz>
          <iyy>2.54167E-05</iyy>
          <iyz>0</iyz>
          <izz>7.20833E-05</izz>
        </inertia>
      </inertial>
      <collision name="collision">
        <geometry>
          <box>
            <size>0.110 0.150 0.010</size>
          </box>
        </geometry>
      </collision>
      <visual name="visual">
        <geometry>
          <box>
            <size>0.110 0.150 0.010</size>
          </box>
        </geometry>
        <material>
          <ambient>0.9 0.9 0.9 1</ambient>
          <diffuse>0.9 0.9 0.9 1</diffuse>
          <specular>0.1 0.1 0.1 1</specular>
        </material>
      </visual>
      <visual name="motor_visual">
        <pose degrees="true">0.05 0 0 0 90 0</pose>
        <geometry>
          <cylinder>
            <radius>0.012</radius>
            <length>0.026</length>
          </cylinder>
        </geometry>
        <material>
          <ambient>0 0 1 1</ambient>
          <diffuse>0 0 1 1</diffuse>
          <specular>0.1 0.1 0.1 1</specular>
        </material>
      </visual>
      <!-- debug visual for lift-drag centre of pressure -->
      <visual name="cp_visual">
        <pose>0.0275 0 0 0 0 0</pose>
        <geometry>
          <sphere>
            <radius>0.01</radius>
          </sphere>
        </geometry>
        <material>
          <ambient>1 0 0 1</ambient>
          <diffuse>1 0 0 1</diffuse>
          <specular>0.1 0.1 0.1 1</specular>
        </material>
      </visual>
    </link>
    <joint name="wing_back_right_joint" type="revolute">
      <pose>0.0275 0.075 0 0 0 0</pose>
      <parent>fuselage_back_link</parent>
      <child>wing_back_right_link</child>
      <axis>
        <xyz>0 1 0</xyz>
        <limit>
          <lower>-2.0943951023931953</lower>
          <upper>0.5235987755982988</upper>
        </limit>
        <dynamics>
          <damping>0.01</damping>
        </dynamics>
      </axis>
    </joint>

    <link name="motor_front_left_link">
      <pose degrees="true">0.1225 0.125 0 0 90 0</pose>
      <inertial>
        <mass>0.033</mass>
        <inertia>
          <ixx>3.25325E-06</ixx>
          <ixy>0</ixy>
          <ixz>0</ixz>
          <iyy>3.25325E-06</iyy>
          <iyz>0</iyz>
          <izz>2.7885E-06</izz>
        </inertia>
      </inertial>
      <collision name="collision">
        <geometry>
          <cylinder>
            <radius>0.013</radius>
            <length>0.026</length>
          </cylinder>
        </geometry>
      </collision>
      <visual name="visual">
        <geometry>
          <cylinder>
            <radius>0.013</radius>
            <length>0.026</length>
          </cylinder>
        </geometry>
        <material>
          <ambient>0.1 0.1 0.1 1</ambient>
          <diffuse>0.1 0.1 0.1 1</diffuse>
          <specular>0.1 0.1 0.1 1</specular>
        </material>
      </visual>
      <visual name="prop_blade_1_visual">
        <pose degrees="true">0.030625 0 0.015 0 0 0</pose>
        <geometry>
          <box>
            <size>0.06125 0.01 0.002</size>
          </box>
        </geometry>
        <material>
          <ambient>0 1 0 1</ambient>
          <diffuse>0 1 0 1</diffuse>
          <specular>0.1 0.1 0.1 1</specular>
        </material>
      </visual>
      <visual name="prop_blade_2_visual">
        <pose degrees="true">-0.0153125 0.026522027990898433 0.015 0 0 120</pose>
        <geometry>
          <box>
            <size>0.06125 0.01 0.002</size>
          </box>
        </geometry>
        <material>
          <ambient>0 1 0 1</ambient>
          <diffuse>0 1 0 1</diffuse>
          <specular>0.1 0.1 0.1 1</specular>
        </material>
      </visual>
      <visual name="prop_blade_3_visual">
        <pose degrees="true">-0.0153125 -0.026522027990898433 0.015 0 0 240</pose>
        <geometry>
          <box>
            <size>0.06125 0.01 0.002</size>
          </box>
        </geometry>
        <material>
          <ambient>0 1 0 1</ambient>
          <diffuse>0 1 0 1</diffuse>
          <specular>0.1 0.1 0.1 1</specular>
        </material>
      </visual>
    </link>
    <joint name="motor_front_left_joint" type="revolute">
      <pose>0 0 0 0 0 0</pose>
      <parent>wing_front_left_link</parent>
      <child>motor_front_left_link</child>
      <axis>
        <xyz>0 0 1</xyz>
        <limit>
          <lower>-1.0e16</lower>
          <upper>1.0e16</upper>
        </limit>
        <dynamics>
          <damping>0.004</damping>
        </dynamics>
      </axis>
    </joint>

    <link name="motor_front_right_link">
      <pose degrees="true">0.1225 -0.125 0 0 90 0</pose>
      <inertial>
        <mass>0.033</mass>
        <inertia>
          <ixx>3.25325E-06</ixx>
          <ixy>0</ixy>
          <ixz>0</ixz>
          <iyy>3.25325E-06</iyy>
          <iyz>0</iyz>
          <izz>2.7885E-06</izz>
        </inertia>
      </inertial>
      <collision name="collision">
        <geometry>
          <cylinder>
            <radius>0.013</radius>
            <length>0.026</length>
          </cylinder>
        </geometry>
      </collision>
      <visual name="visual">
        <geometry>
          <cylinder>
            <radius>0.013</radius>
            <length>0.026</length>
          </cylinder>
        </geometry>
        <material>
          <ambient>0.1 0.1 0.1 1</ambient>
          <diffuse>0.1 0.1 0.1 1</diffuse>
          <specular>0.1 0.1 0.1 1</specular>
        </material>
      </visual>
      <visual name="prop_blade_1_visual">
        <pose degrees="true">0.030625 0 0.015 0 0 0</pose>
        <geometry>
          <box>
            <size>0.06125 0.01 0.002</size>
          </box>
        </geometry>
        <material>
          <ambient>0 0 1 1</ambient>
          <diffuse>0 0 1 1</diffuse>
          <specular>0.1 0.1 0.1 1</specular>
        </material>
      </visual>
      <visual name="prop_blade_2_visual">
        <pose degrees="true">-0.0153125 0.026522027990898433 0.015 0 0 120</pose>
        <geometry>
          <box>
            <size>0.06125 0.01 0.002</size>
          </box>
        </geometry>
        <material>
          <ambient>0 0 1 1</ambient>
          <diffuse>0 0 1 1</diffuse>
          <specular>0.1 0.1 0.1 1</specular>
        </material>
      </visual>
      <visual name="prop_blade_3_visual">
        <pose degrees="true">-0.0153125 -0.026522027990898433 0.015 0 0 240</pose>
        <geometry>
          <box>
            <size>0.06125 0.01 0.002</size>
          </box>
        </geometry>
        <material>
          <ambient>0 0 1 1</ambient>
          <diffuse>0 0 1 1</diffuse>
          <specular>0.1 0.1 0.1 1</specular>
        </material>
      </visual>
    </link>
    <joint name="motor_front_right_joint" type="revolute">
      <pose>0 0 0 0 0 0</pose>
      <parent>wing_front_right_link</parent>
      <child>motor_front_right_link</child>
      <axis>
        <xyz>0 0 1</xyz>
        <limit>
          <lower>-1.0e16</lower>
          <upper>1.0e16</upper>
        </limit>
        <dynamics>
          <damping>0.004</damping>
        </dynamics>
      </axis>
    </joint>

    <link name="motor_back_left_link">
      <pose degrees="true">-0.0675 0.125 0 0 90 0</pose>
      <inertial>
        <mass>0.033</mass>
        <inertia>
          <ixx>3.25325E-06</ixx>
          <ixy>0</ixy>
          <ixz>0</ixz>
          <iyy>3.25325E-06</iyy>
          <iyz>0</iyz>
          <izz>2.7885E-06</izz>
        </inertia>
      </inertial>
      <collision name="collision">
        <geometry>
          <cylinder>
            <radius>0.013</radius>
            <length>0.026</length>
          </cylinder>
        </geometry>
      </collision>
      <visual name="visual">
        <geometry>
          <cylinder>
            <radius>0.013</radius>
            <length>0.026</length>
          </cylinder>
        </geometry>
        <material>
          <ambient>0.1 0.1 0.1 1</ambient>
          <diffuse>0.1 0.1 0.1 1</diffuse>
          <specular>0.1 0.1 0.1 1</specular>
        </material>
      </visual>
      <visual name="prop_blade_1_visual">
        <pose degrees="true">0.030625 0 0.015 0 0 0</pose>
        <geometry>
          <box>
            <size>0.06125 0.01 0.002</size>
          </box>
        </geometry>
        <material>
          <ambient>0 0 1 1</ambient>
          <diffuse>0 0 1 1</diffuse>
          <specular>0.1 0.1 0.1 1</specular>
        </material>
      </visual>
      <visual name="prop_blade_2_visual">
        <pose degrees="true">-0.0153125 0.026522027990898433 0.015 0 0 120</pose>
        <geometry>
          <box>
            <size>0.06125 0.01 0.002</size>
          </box>
        </geometry>
        <material>
          <ambient>0 0 1 1</ambient>
          <diffuse>0 0 1 1</diffuse>
          <specular>0.1 0.1 0.1 1</specular>
        </material>
      </visual>
      <visual name="prop_blade_3_visual">
        <pose degrees="true">-0.0153125 -0.026522027990898433 0.015 0 0 240</pose>
        <geometry>
          <box>
            <size>0.06125 0.01 0.002</size>
          </box>
        </geometry>
        <material>
          <ambient>0 0 1 1</ambient>
          <diffuse>0 0 1 1</diffuse>
          <specular>0.1 0.1 0.1 1</specular>
        </material>
      </visual>
    </link>
    <joint name="motor_back_left_joint" type="revolute">
      <pose>0 0 0 0 0 0</pose>
      <parent>wing_back_left_link</parent>
      <child>motor_back_left_link</child>
      <axis>
        <xyz>0 0 1</xyz>
        <limit>
          <lower>-1.0e16</lower>
          <upper>1.0e16</upper>
        </limit>
        <dynamics>
          <damping>0.004</damping>
        </dynamics>
      </axis>
    </joint>

    <link name="motor_back_right_link">
      <pose degrees="true">-0.0675 -0.125 0 0 90 0</pose>
      <inertial>
        <mass>0.033</mass>
        <inertia>
          <ixx>3.25325E-06</ixx>
          <ixy>0</ixy>
          <ixz>0</ixz>
          <iyy>3.25325E-06</iyy>
          <iyz>0</iyz>
          <izz>2.7885E-06</izz>
        </inertia>
      </inertial>
      <collision name="collision">
        <geometry>
          <cylinder>
            <radius>0.013</radius>
            <length>0.026</length>
          </cylinder>
        </geometry>
      </collision>
      <visual name="visual">
        <geometry>
          <cylinder>
            <radius>0.013</radius>
            <length>0.026</length>
          </cylinder>
        </geometry>
        <material>
          <ambient>0.1 0.1 0.1 1</ambient>
          <diffuse>0.1 0.1 0.1 1</diffuse>
          <specular>0.1 0.1 0.1 1</specular>
        </material>
      </visual>
      <visual name="prop_blade_1_visual">
        <pose degrees="true">0.030625 0 0.015 0 0 0</pose>
        <geometry>
          <box>
            <size>0.06125 0.01 0.002</size>
          </box>
        </geometry>
        <material>
          <ambient>0 1 0 1</ambient>
          <diffuse>0 1 0 1</diffuse>
          <specular>0.1 0.1 0.1 1</specular>
        </material>
      </visual>
      <visual name="prop_blade_2_visual">
        <pose degrees="true">-0.0153125 0.026522027990898433 0.015 0 0 120</pose>
        <geometry>
          <box>
            <size>0.06125 0.01 0.002</size>
          </box>
        </geometry>
        <material>
          <ambient>0 1 0 1</ambient>
          <diffuse>0 1 0 1</diffuse>
          <specular>0.1 0.1 0.1 1</specular>
        </material>
      </visual>
      <visual name="prop_blade_3_visual">
        <pose degrees="true">-0.0153125 -0.026522027990898433 0.015 0 0 240</pose>
        <geometry>
          <box>
            <size>0.06125 0.01 0.002</size>
          </box>
        </geometry>
        <material>
          <ambient>0 1 0 1</ambient>
          <diffuse>0 1 0 1</diffuse>
          <specular>0.1 0.1 0.1 1</specular>
        </material>
      </visual>
    </link>
    <joint name="motor_back_right_joint" type="revolute">
      <pose>0 0 0 0 0 0</pose>
      <parent>wing_back_right_link</parent>
      <child>motor_back_right_link</child>
      <axis>
        <xyz>0 0 1</xyz>
        <limit>
          <lower>-1.0e16</lower>
          <upper>1.0e16</upper>
        </limit>
        <dynamics>
          <damping>0.004</damping>
        </dynamics>
      </axis>
    </joint>

    <!-- plugins -->
    <plugin name="gz::sim::systems::JointStatePublisher"
        filename="gz-sim-joint-state-publisher-system">
    </plugin>

    <!-- wing position controllers -->
    <plugin name="gz::sim::systems::JointPositionController"
        filename="gz-sim-joint-position-controller-system">
      <joint_name>wing_front_left_joint</joint_name>
      <topic>/model/morphing_quad/joint/wing_front_left_joint/cmd_pos</topic>
      <initial_position>0</initial_position>
      <p_gain>0.4</p_gain>
      <i_gain>0</i_gain>
      <d_gain>1.0e-2</d_gain>
      <i_max>1</i_max>
      <i_min>-1</i_min>
      <cmd_max>1.0e4</cmd_max>
      <cmd_min>-1.0e4</cmd_min>
    </plugin>
    <plugin name="gz::sim::systems::JointPositionController"
        filename="gz-sim-joint-position-controller-system">
      <joint_name>wing_front_right_joint</joint_name>
      <topic>/model/morphing_quad/joint/wing_front_right_joint/cmd_pos</topic>
      <initial_position>0</initial_position>
      <p_gain>0.4</p_gain>
      <i_gain>0</i_gain>
      <d_gain>1.0e-2</d_gain>
      <i_max>1</i_max>
      <i_min>-1</i_min>
      <cmd_max>1.0e4</cmd_max>
      <cmd_min>-1.0e4</cmd_min>
    </plugin>
    <plugin name="gz::sim::systems::JointPositionController"
        filename="gz-sim-joint-position-controller-system">
      <joint_name>wing_back_left_joint</joint_name>
      <topic>/model/morphing_quad/joint/wing_back_left_joint/cmd_pos</topic>
      <initial_position>0</initial_position>
      <p_gain>0.4</p_gain>
      <i_gain>0</i_gain>
      <d_gain>1.0e-2</d_gain>
      <i_max>1</i_max>
      <i_min>-1</i_min>
      <cmd_max>1.0e4</cmd_max>
      <cmd_min>-1.0e4</cmd_min>
    </plugin>
    <plugin name="gz::sim::systems::JointPositionController"
        filename="gz-sim-joint-position-controller-system">
      <joint_name>wing_back_right_joint</joint_name>
      <topic>/model/morphing_quad/joint/wing_back_right_joint/cmd_pos</topic>
      <initial_position>0</initial_position>
      <p_gain>0.4</p_gain>
      <i_gain>0</i_gain>
      <d_gain>1.0e-2</d_gain>
      <i_max>1</i_max>
      <i_min>-1</i_min>
      <cmd_max>1.0e4</cmd_max>
      <cmd_min>-1.0e4</cmd_min>
    </plugin>

    <!-- motor velocity controllers -->
    <!-- <plugin name="gz::sim::systems::JointController"
      filename="gz-sim-joint-controller-system">
      <joint_name>motor_front_left_joint</joint_name>
      <use_force_commands>1</use_force_commands>
      <topic>/model/morphing_quad/joint/motor_front_left_joint/cmd_vel</topic>
      <initial_velocity>0.0</initial_velocity>
      <p_gain>0.008</p_gain>
      <i_gain>0</i_gain>
      <d_gain>1.0e-7</d_gain>
      <i_max>-1</i_max>
      <i_min>0</i_min>
      <cmd_max>100.0</cmd_max>
      <cmd_min>-100.0</cmd_min>
    </plugin>
    <plugin name="gz::sim::systems::JointController"
      filename="gz-sim-joint-controller-system">
      <joint_name>motor_front_right_joint</joint_name>
      <use_force_commands>1</use_force_commands>
      <topic>/model/morphing_quad/joint/motor_front_right_joint/cmd_vel</topic>
      <initial_velocity>0.0</initial_velocity>
      <p_gain>0.008</p_gain>
      <i_gain>0</i_gain>
      <d_gain>1.0e-7</d_gain>
      <i_max>-1</i_max>
      <i_min>0</i_min>
      <cmd_max>100.0</cmd_max>
      <cmd_min>-100.0</cmd_min>
    </plugin>
    <plugin name="gz::sim::systems::JointController"
      filename="gz-sim-joint-controller-system">
      <joint_name>motor_back_left_joint</joint_name>
      <use_force_commands>1</use_force_commands>
      <topic>/model/morphing_quad/joint/motor_back_left_joint/cmd_vel</topic>
      <initial_velocity>0.0</initial_velocity>
      <p_gain>0.008</p_gain>
      <i_gain>0</i_gain>
      <d_gain>1.0e-7</d_gain>
      <i_max>-1</i_max>
      <i_min>0</i_min>
      <cmd_max>100.0</cmd_max>
      <cmd_min>-100.0</cmd_min>
    </plugin>
    <plugin name="gz::sim::systems::JointController"
      filename="gz-sim-joint-controller-system">
      <joint_name>motor_back_right_joint</joint_name>
      <use_force_commands>1</use_force_commands>
      <topic>/model/morphing_quad/joint/motor_back_right_joint/cmd_vel</topic>
      <initial_velocity>0.0</initial_velocity>
      <p_gain>0.008</p_gain>
      <i_gain>0</i_gain>
      <d_gain>1.0e-7</d_gain>
      <i_max>-1</i_max>
      <i_min>0</i_min>
      <cmd_max>100.0</cmd_max>
      <cmd_min>-100.0</cmd_min>
    </plugin> -->

    <!-- motor1 prop blades, ccw, motor_front_right_link -->
    <plugin name="gz::sim::systems::LiftDrag"
      filename="gz-sim-lift-drag-system">
      <a0>0.3</a0>
      <alpha_stall>1.4</alpha_stall>
      <cla>4.2500</cla>
      <cda>0.10</cda>
      <cma>0.00</cma>
      <cla_stall>-0.025</cla_stall>
      <cda_stall>0.0</cda_stall>
      <cma_stall>0.0</cma_stall>
      <area>0.0015</area>
      <air_density>1.2041</air_density>
      <cp>0.063 0 0</cp>
      <forward>0 1 0</forward>
      <upward>0 0 1</upward>
      <link_name>motor_front_right_link</link_name>
    </plugin>
    <plugin name="gz::sim::systems::LiftDrag"
      filename="gz-sim-lift-drag-system">
      <a0>0.3</a0>
      <alpha_stall>1.4</alpha_stall>
      <cla>4.2500</cla>
      <cda>0.10</cda>
      <cma>0.00</cma>
      <cla_stall>-0.025</cla_stall>
      <cda_stall>0.0</cda_stall>
      <cma_stall>0.0</cma_stall>
      <area>0.0015</area>
      <air_density>1.2041</air_density>
      <cp>-0.0315 0.0545596 0</cp>
      <forward>-0.866025404 -0.5 0</forward>
      <upward>0 0 1</upward>
      <link_name>motor_front_right_link</link_name>
    </plugin>
    <plugin name="gz::sim::systems::LiftDrag"
      filename="gz-sim-lift-drag-system">
      <a0>0.3</a0>
      <alpha_stall>1.4</alpha_stall>
      <cla>4.2500</cla>
      <cda>0.10</cda>
      <cma>0.00</cma>
      <cla_stall>-0.025</cla_stall>
      <cda_stall>0.0</cda_stall>
      <cma_stall>0.0</cma_stall>
      <area>0.0015</area>
      <air_density>1.2041</air_density>
      <cp>-0.0315 -0.0545596 0</cp>
      <forward>0.866025404 -0.5 0</forward>
      <upward>0 0 1</upward>
      <link_name>motor_front_right_link</link_name>
    </plugin>

    <!-- motor2 prop blades, ccw, motor_back_left_link -->
    <plugin name="gz::sim::systems::LiftDrag"
      filename="gz-sim-lift-drag-system">
      <a0>0.3</a0>
      <alpha_stall>1.4</alpha_stall>
      <cla>4.2500</cla>
      <cda>0.10</cda>
      <cma>0.00</cma>
      <cla_stall>-0.025</cla_stall>
      <cda_stall>0.0</cda_stall>
      <cma_stall>0.0</cma_stall>
      <area>0.0015</area>
      <air_density>1.2041</air_density>
      <cp>0.063 0 0</cp>
      <forward>0 1 0</forward>
      <upward>0 0 1</upward>
      <link_name>motor_back_left_link</link_name>
    </plugin>
    <plugin name="gz::sim::systems::LiftDrag"
      filename="gz-sim-lift-drag-system">
      <a0>0.3</a0>
      <alpha_stall>1.4</alpha_stall>
      <cla>4.2500</cla>
      <cda>0.10</cda>
      <cma>0.00</cma>
      <cla_stall>-0.025</cla_stall>
      <cda_stall>0.0</cda_stall>
      <cma_stall>0.0</cma_stall>
      <area>0.0015</area>
      <air_density>1.2041</air_density>
      <cp>-0.0315 0.0545596 0</cp>
      <forward>-0.866025404 -0.5 0</forward>
      <upward>0 0 1</upward>
      <link_name>motor_back_left_link</link_name>
    </plugin>
    <plugin name="gz::sim::systems::LiftDrag"
      filename="gz-sim-lift-drag-system">
      <a0>0.3</a0>
      <alpha_stall>1.4</alpha_stall>
      <cla>4.2500</cla>
      <cda>0.10</cda>
      <cma>0.00</cma>
      <cla_stall>-0.025</cla_stall>
      <cda_stall>0.0</cda_stall>
      <cma_stall>0.0</cma_stall>
      <area>0.0015</area>
      <air_density>1.2041</air_density>
      <cp>-0.0315 -0.0545596 0</cp>
      <forward>0.866025404 -0.5 0</forward>
      <upward>0 0 1</upward>
      <link_name>motor_back_left_link</link_name>
    </plugin>

    <!-- motor3 prop blade, cw, motor_front_left_link -->
    <plugin name="gz::sim::systems::LiftDrag"
      filename="gz-sim-lift-drag-system">
      <a0>0.3</a0>
      <alpha_stall>1.4</alpha_stall>
      <cla>4.2500</cla>
      <cda>0.10</cda>
      <cma>0.00</cma>
      <cla_stall>-0.025</cla_stall>
      <cda_stall>0.0</cda_stall>
      <cma_stall>0.0</cma_stall>
      <area>0.0015</area>
      <air_density>1.2041</air_density>
      <cp>0.063 0 0</cp>
      <forward>0 -1 0</forward>
      <upward>0 0 1</upward>
      <link_name>motor_front_left_link</link_name>
    </plugin>
    <plugin name="gz::sim::systems::LiftDrag"
      filename="gz-sim-lift-drag-system">
      <a0>0.3</a0>
      <alpha_stall>1.4</alpha_stall>
      <cla>4.2500</cla>
      <cda>0.10</cda>
      <cma>0.00</cma>
      <cla_stall>-0.025</cla_stall>
      <cda_stall>0.0</cda_stall>
      <cma_stall>0.0</cma_stall>
      <area>0.0015</area>
      <air_density>1.2041</air_density>
      <cp>-0.0315 0.0545596 0</cp>
      <forward>0.866025404 0.5 0</forward>
      <upward>0 0 1</upward>
      <link_name>motor_front_left_link</link_name>
    </plugin>
    <plugin name="gz::sim::systems::LiftDrag"
      filename="gz-sim-lift-drag-system">
      <a0>0.3</a0>
      <alpha_stall>1.4</alpha_stall>
      <cla>4.2500</cla>
      <cda>0.10</cda>
      <cma>0.00</cma>
      <cla_stall>-0.025</cla_stall>
      <cda_stall>0.0</cda_stall>
      <cma_stall>0.0</cma_stall>
      <area>0.0015</area>
      <air_density>1.2041</air_density>
      <cp>-0.0315 -0.0545596 0</cp>
      <forward>-0.866025404 0.5 0</forward>
      <upward>0 0 1</upward>
      <link_name>motor_front_left_link</link_name>
    </plugin>

    <!-- motor4 prop blades, cw, motor_back_right_link -->
    <plugin name="gz::sim::systems::LiftDrag"
      filename="gz-sim-lift-drag-system">
      <a0>0.3</a0>
      <alpha_stall>1.4</alpha_stall>
      <cla>4.2500</cla>
      <cda>0.10</cda>
      <cma>0.00</cma>
      <cla_stall>-0.025</cla_stall>
      <cda_stall>0.0</cda_stall>
      <cma_stall>0.0</cma_stall>
      <area>0.0015</area>
      <air_density>1.2041</air_density>
      <cp>0.063 0 0</cp>
      <forward>0 -1 0</forward>
      <upward>0 0 1</upward>
      <link_name>motor_back_right_link</link_name>
    </plugin>
    <plugin name="gz::sim::systems::LiftDrag"
      filename="gz-sim-lift-drag-system">
      <a0>0.3</a0>
      <alpha_stall>1.4</alpha_stall>
      <cla>4.2500</cla>
      <cda>0.10</cda>
      <cma>0.00</cma>
      <cla_stall>-0.025</cla_stall>
      <cda_stall>0.0</cda_stall>
      <cma_stall>0.0</cma_stall>
      <area>0.0015</area>
      <air_density>1.2041</air_density>
      <cp>-0.0315 0.0545596 0</cp>
      <forward>0.866025404 0.5 0</forward>
      <upward>0 0 1</upward>
      <link_name>motor_back_right_link</link_name>
    </plugin>
    <plugin name="gz::sim::systems::LiftDrag"
      filename="gz-sim-lift-drag-system">
      <a0>0.3</a0>
      <alpha_stall>1.4</alpha_stall>
      <cla>4.2500</cla>
      <cda>0.10</cda>
      <cma>0.00</cma>
      <cla_stall>-0.025</cla_stall>
      <cda_stall>0.0</cda_stall>
      <cma_stall>0.0</cma_stall>
      <area>0.0015</area>
      <air_density>1.2041</air_density>
      <cp>-0.0315 -0.0545596 0</cp>
      <forward>-0.866025404 0.5 0</forward>
      <upward>0 0 1</upward>
      <link_name>motor_back_right_link</link_name>
    </plugin>

    <!-- wings -->
    <plugin filename="gz-sim-lift-drag-system"
        name="gz::sim::systems::LiftDrag">
      <a0>0.13</a0>
      <cla>3.7</cla>
      <cda>0.06417112299</cda>
      <cma>0.0</cma>
      <alpha_stall>0.3391428111</alpha_stall>
      <cla_stall>-3.85</cla_stall>
      <cda_stall>-0.9233984055</cda_stall>
      <cma_stall>0.0</cma_stall>
      <cp>0.0275 0 0</cp>
      <area>0.03</area>
      <air_density>1.2041</air_density>
      <forward>1 0 0</forward>
      <upward>0 0 1</upward>
      <link_name>wing_front_right_link</link_name>
    </plugin>
    <plugin filename="gz-sim-lift-drag-system"
        name="gz::sim::systems::LiftDrag">
      <a0>0.13</a0>
      <cla>3.7</cla>
      <cda>0.06417112299</cda>
      <cma>0.0</cma>
      <alpha_stall>0.3391428111</alpha_stall>
      <cla_stall>-3.85</cla_stall>
      <cda_stall>-0.9233984055</cda_stall>
      <cma_stall>0.0</cma_stall>
      <cp>0.0275 0 0</cp>
      <area>0.03</area>
      <air_density>1.2041</air_density>
      <forward>1 0 0</forward>
      <upward>0 0 1</upward>
      <link_name>wing_front_left_link</link_name>
    </plugin>
    <plugin filename="gz-sim-lift-drag-system"
        name="gz::sim::systems::LiftDrag">
      <a0>0.13</a0>
      <cla>3.7</cla>
      <cda>0.06417112299</cda>
      <cma>0.0</cma>
      <alpha_stall>0.3391428111</alpha_stall>
      <cla_stall>-3.85</cla_stall>
      <cda_stall>-0.9233984055</cda_stall>
      <cma_stall>0.0</cma_stall>
      <cp>0.0275 0 0</cp>
      <area>0.03</area>
      <air_density>1.2041</air_density>
      <forward>1 0 0</forward>
      <upward>0 0 1</upward>
      <link_name>wing_back_right_link</link_name>
    </plugin>
    <plugin filename="gz-sim-lift-drag-system"
        name="gz::sim::systems::LiftDrag">
      <a0>0.13</a0>
      <cla>3.7</cla>
      <cda>0.06417112299</cda>
      <cma>0.0</cma>
      <alpha_stall>0.3391428111</alpha_stall>
      <cla_stall>-3.85</cla_stall>
      <cda_stall>-0.9233984055</cda_stall>
      <cma_stall>0.0</cma_stall>
      <cp>0.0275 0 0</cp>
      <area>0.03</area>
      <air_density>1.2041</air_density>
      <forward>1 0 0</forward>
      <upward>0 0 1</upward>
      <link_name>wing_back_left_link</link_name>
    </plugin>

    <plugin name="ArduPilotPlugin" filename="ArduPilotPlugin">
      <!-- Port settings -->
      <fdm_addr>127.0.0.1</fdm_addr>
      <fdm_port_in>9002</fdm_port_in>
      <connectionTimeoutMaxCount>5</connectionTimeoutMaxCount>
      <lock_step>1</lock_step>
      <have_32_channels>0</have_32_channels>

      <!-- Frame conventions -->
      <modelXYZToAirplaneXForwardZDown degrees="true">0 0 0 180 0 0</modelXYZToAirplaneXForwardZDown>
      <gazeboXYZToNED degrees="true">0 0 0 180 0 90</gazeboXYZToNED>

      <!-- Sensors -->
      <imuName>base_link::imu_sensor</imuName>

      <!-- motor1: ccw -->
      <control channel="4">
        <jointName>motor_front_right_joint</jointName>
        <multiplier>1500</multiplier>
        <offset>0</offset>
        <servo_min>1000</servo_min>
        <servo_max>2000</servo_max>

        <useForce>1</useForce>
        <type>VELOCITY</type>
        <p_gain>0.008</p_gain>
        <i_gain>0</i_gain>
        <d_gain>1.0e-7</d_gain>
        <i_max>-1</i_max>
        <i_min>0</i_min>
        <cmd_max>100.0</cmd_max>
        <cmd_min>-100.0</cmd_min>

        <!-- <type>COMMAND</type>
        <cmd_topic>/model/morphing_quad/joint/motor_front_right_joint/cmd_vel</cmd_topic> -->
      </control>

      <!-- motor2: ccw -->
      <control channel="5">
        <jointName>motor_back_left_joint</jointName>
        <multiplier>1500</multiplier>
        <offset>0</offset>
        <servo_min>1000</servo_min>
        <servo_max>2000</servo_max>

        <useForce>1</useForce>
        <type>VELOCITY</type>
        <p_gain>0.008</p_gain>
        <i_gain>0</i_gain>
        <d_gain>1.0e-7</d_gain>
        <i_max>-1</i_max>
        <i_min>0</i_min>
        <cmd_max>100.0</cmd_max>
        <cmd_min>-100.0</cmd_min>

        <!-- <type>COMMAND</type>
        <cmd_topic>/model/morphing_quad/joint/motor_back_left_joint/cmd_vel</cmd_topic> -->
      </control>

      <!-- motor3: cw -->
      <control channel="6">
          <jointName>motor_front_left_joint</jointName>
          <multiplier>-1500</multiplier>
          <offset>0</offset>
          <servo_min>1000</servo_min>
          <servo_max>2000</servo_max>

          <useForce>1</useForce>
          <type>VELOCITY</type>
          <p_gain>0.008</p_gain>
          <i_gain>0</i_gain>
          <d_gain>1.0e-7</d_gain>
          <i_max>-1</i_max>
          <i_min>0</i_min>
          <cmd_max>100.0</cmd_max>
          <cmd_min>-100.0</cmd_min>
    
          <!-- <type>COMMAND</type>
          <cmd_topic>/model/morphing_quad/joint/motor_front_left_joint/cmd_vel</cmd_topic> -->
        </control>
  
      <!-- motor4: cw -->
      <control channel="7">
          <jointName>motor_back_right_joint</jointName>
          <multiplier>-1500</multiplier>
          <offset>0</offset>
          <servo_min>1000</servo_min>
          <servo_max>2000</servo_max>

          <useForce>1</useForce>
          <type>VELOCITY</type>
          <p_gain>0.008</p_gain>
          <i_gain>0</i_gain>
          <d_gain>1.0e-7</d_gain>
          <i_max>-1</i_max>
          <i_min>0</i_min>
          <cmd_max>100.0</cmd_max>
          <cmd_min>-100.0</cmd_min>
    
          <!-- <type>COMMAND</type>
          <cmd_topic>/model/morphing_quad/joint/motor_back_right_joint/cmd_vel</cmd_topic> -->
        </control>

      <!-- front wing tilt -->
      <control channel="8">
        <jointName>wing_front_left_joint</jointName>
        <multiplier>-2.6179938779914944</multiplier>
        <offset>-0.2</offset>
        <servo_min>1000</servo_min>
        <servo_max>2000</servo_max>
        <type>COMMAND</type>
        <cmd_topic>/model/morphing_quad/joint/wing_front_left_joint/cmd_pos</cmd_topic>
      </control>
      <control channel="9">
        <jointName>wing_front_right_joint</jointName>
        <multiplier>-2.6179938779914944</multiplier>
        <offset>-0.2</offset>
        <servo_min>1000</servo_min>
        <servo_max>2000</servo_max>
        <type>COMMAND</type>
        <cmd_topic>/model/morphing_quad/joint/wing_front_right_joint/cmd_pos</cmd_topic>
      </control>

      <!-- rear wing tilt -->
      <control channel="10">
        <jointName>wing_back_left_joint</jointName>
        <multiplier>-2.6179938779914944</multiplier>
        <offset>-0.2</offset>
        <servo_min>1000</servo_min>
        <servo_max>2000</servo_max>
        <type>COMMAND</type>
        <cmd_topic>/model/morphing_quad/joint/wing_back_left_joint/cmd_pos</cmd_topic>
      </control>
      <control channel="11">
        <jointName>wing_back_right_joint</jointName>
        <multiplier>-2.6179938779914944</multiplier>
        <offset>-0.2</offset>
        <servo_min>1000</servo_min>
        <servo_max>2000</servo_max>
        <type>COMMAND</type>
        <cmd_topic>/model/morphing_quad/joint/wing_back_right_joint/cmd_pos</cmd_topic>
      </control>
    </plugin>
  </model>
</sdf>
